Workbook

Sheet Read Me
A1: Enterprise Software Growth Capital Model
A2: Illustrative underwriting of Northstar Workflow Systems
A4: Disclosure | B4: Northstar Workflow Systems is a hypothetical company created solely for an illustrative underwriting exercise. It is not a real business or investment opportunity.
A5: Purpose | B5: This workbook underwrites a single hypothetical B2B enterprise SaaS company across three capital structures: all growth equity, all private credit, and a blended structure combining both. The operating forecast is identical in every case, so any difference in outcome is caused by the structure rather than by the business.
A6: How to use it | B6: Every input lives on the Assumptions sheet and is shaded amber. Change any amber cell and the entire workbook recalculates, including the SaaS metrics, the debt schedules, the returns, the sensitivities, and the downside case. No output anywhere in this workbook is a hardcoded number.
A7: Colour convention | B7: Amber cells are inputs you may change. White cells are formulas driven by those inputs. Grey banded rows are subtotals. Red shading appears only where a minimum cash covenant is breached or EBITDA is negative, so the formatting carries meaning rather than decoration.
A8: Sheet order | B8: Read Me, IC Summary, Assumptions, Historical Financials, Operating Forecast, SaaS Metrics, Capital Structures, Growth Equity Case, Private Credit Case, Blended Capital Case, Debt Schedule, Returns Analysis, Sensitivities, Downside Case, Model Checks, Sources and Disclosures.
A9: Key formula: ARR bridge | B9: Ending ARR = Beginning ARR + New ARR + Expansion ARR less Churned ARR. Churned ARR is set by gross retention and Expansion ARR by the gap between net and gross retention. New ARR is then the residual required to hit the growth target, which makes the sales requirement explicit rather than assumed. If you lower net revenue retention, required New ARR rises automatically.
A10: Key formula: Revenue | B10: Revenue = average of beginning and ending ARR for the year. ARR is added through the year rather than on day one, so recognising the full ending ARR as revenue would overstate the period.
A11: Key formula: Unlevered free cash flow | B11: EBITDA less capital expenditure plus the deferred revenue benefit on ARR growth. It is stated before any interest or principal so the same cash flow line can be used across all three structures.
A12: Key formula: Debt service | B12: Cash interest on the opening balance, plus amortisation once the interest only period ends. PIK interest, if switched on, accretes to the balance rather than being paid in cash.
A13: Key formula: Exit equity value | B13: Exit enterprise value at the exit ARR multiple, plus ending cash, less ending debt. The equity investor receives their ownership percentage of that.
A14: What this workbook is not | B14: It is not a valuation of any real company, not an investment recommendation, and not a forecast. It is a demonstration of how a structure decision changes dilution, debt service risk, covenant headroom, runway, and returns when the underlying business is held constant.
A15: Key correction | B15: Existing holder value is calculated from each structure's actual exit equity value. The selected blend retains approximately USD 9.7 million more for existing holders than all equity; applying the dilution difference to one common equity value would overstate the benefit.
A16: Built by | B16: Sahil Modi, modi.sahil@gmail.com

Sheet IC Summary
A1: Investment Committee Summary
A2: Northstar Workflow Systems - hypothetical SaaS growth capital underwriting
A3: All figures are hypothetical and illustrative. This is a preliminary structure analysis, not an actual investment recommendation.
A5: Company and transaction snapshot
A6: Beginning ARR | C6: Year 1 ARR growth | E6: Net revenue retention | G6: Gross retention
A7: =Assumptions!B6 -> 12 | C7: =Assumptions!B7 -> 0.3 | E7: =Assumptions!B9 -> 1.1 | G7: =Assumptions!B10 -> 0.88
A8: Gross margin | C8: Capital requirement | E8: Entry ARR multiple | G8: Exit ARR multiple
A9: =Assumptions!B11 -> 0.78 | C9: =Assumptions!B26 -> 20 | E9: =Assumptions!B28 -> 8 | G9: =Assumptions!B29 -> 7
A11: Structure comparison
A12: Metric | B12: Growth equity | C12: Private credit | D12: Selected blend | E12: Decision lens
A13: Equity invested | B13: ='Capital Structures'!B7 -> 20 | C13: ='Capital Structures'!C7 -> 0 | D13: ='Capital Structures'!D7 -> 8 | E13: Capital source
A14: Debt principal | B14: ='Capital Structures'!B8 -> 0 | C14: ='Capital Structures'!C8 -> 20 | D14: ='Capital Structures'!D8 -> 12 | E14: Capital source
A15: Founder dilution | B15: ='Capital Structures'!B19 -> 0.17241379 | C15: ='Capital Structures'!C19 -> 0 | D15: ='Capital Structures'!D19 -> 0.076923077 | E15: Ownership cost
A16: Year 5 cash | B16: ='Growth Equity Case'!F11 -> 16.045625 | C16: ='Private Credit Case'!F23 -> 2.2606245 | D16: ='Blended Capital Case'!F23 -> 8.1316245 | E16: Liquidity
A17: Minimum cash status | B17: =IF(MIN('Growth Equity Case'!B11:F11)<Assumptions!B30,"BREACH","Headroom") -> Headroom | C17: =IF(MIN('Private Credit Case'!B23:F23)<Assumptions!B30,"BREACH","Headroom") -> BREACH | D17: =IF(MIN('Blended Capital Case'!B23:F23)<Assumptions!B30,"BREACH","Headroom") -> Headroom | E17: Base case covenant
A18: Equity investor MOIC | B18: ='Growth Equity Case'!B27 -> 2.4351429 | C18: ="n/a" -> n/a | D18: ='Blended Capital Case'!B39 -> 2.5361786 | E18: Equity return
A19: Debt investor IRR | B19: ="n/a" -> n/a | C19: ='Returns Analysis'!C30 -> 0.12060048 | D19: ='Returns Analysis'!D30 -> 0.11413376 | E19: Credit return
A20: Downside Year 5 cash | B20: ='Downside Case'!F21 -> 8.3576749 | C20: ='Downside Case'!F22 -> -5.4273251 | D20: ='Downside Case'!F23 -> 0.44367486 | E20: Stress test
A22: Capital sizing and recommendation boundary
A23: Base case capital required to finish with minimum cash | D23: =Assumptions!B27+(-SUM('Operating Forecast'!B28:F28))+SUM('Blended Capital Case'!B11:F11)+Assumptions!B30-Assumptions!B14+'Capital Structures'!D10 -> 16.868375 | E23: Preliminary recommendation The selected USD 8m equity / USD 12m debt blend is the base-case return-maximizing structure. It preserves USD 3.1m of liquidity headroom in the base case and saves existing holders approximately USD 9.7m at exit versus all equity. It is not fully downside-protected: the stress case requires roughly USD 4.6m of additional capital to preserve the USD 5m minimum cash threshold. Final sizing should therefore depend on verified retention, gross margin, burn, and customer concentration.
A24: Gross capital raised | D24: =Assumptions!B26 -> 20
A25: Base case liquidity headroom | D25: =D24-D23 -> 3.1316245
A26: Downside capital required to finish with minimum cash | D26: =Assumptions!B27+(-SUM('Downside Case'!B17:F17))+SUM('Blended Capital Case'!B11:F11)+Assumptions!B30-Assumptions!B14+'Capital Structures'!D10 -> 24.556325
A27: Downside liquidity shortfall at selected blend | D27: =MAX(0,D26-D24) -> 4.5563251
A29: Existing holder value and model controls
A30: Existing holder proceeds - all equity | D30: ='Growth Equity Case'!B23*(1-'Growth Equity Case'!B24) -> 233.77371 | E30: Key controls • Revenue uses average beginning and ending ARR. • New ARR is the residual after churn and expansion. • Cash flows are held constant across structures. • Debt investor returns assume the remaining principal is refinanced or repaid at maturity. • The downside case is separate and does not overwrite base assumptions.
A31: Existing holder proceeds - selected blend | D31: ='Blended Capital Case'!B35*(1-'Blended Capital Case'!B36) -> 243.47314
A32: Incremental value retained by existing holders | D32: =D31-D30 -> 9.6994286
A33: First whole-dollar mix preserving downside minimum cash | D33: =Sensitivities!E66 -> 15

Sheet Assumptions
A1: Assumptions
A2: Every amber cell is an input. Everything else in the workbook derives from these.
A3: All figures are hypothetical and illustrative.
A5: Operating assumptions
A6: Beginning ARR (USD millions) | B6: 12
A7: Year 1 ARR growth rate | B7: 0.3
A8: Annual growth decay (percentage points) | B8: 0.02
A9: Net revenue retention | B9: 1.1
A10: Gross retention | B10: 0.88
A11: Gross margin | B11: 0.78
A12: Capital expenditure (% of revenue) | B12: 0.02
A13: Deferred revenue benefit (% of ARR increase) | B13: 0.1
A14: Beginning cash (USD millions) | B14: 8
A15: Existing debt (USD millions) | B15: 3
A16: Customer count at year 0 | B16: 240
A17: New customer ACV premium to base | B17: 1.15
A19: Operating expense ratios (% of revenue)
A20: Line | B20: Year 1 | C20: Year 2 | D20: Year 3 | E20: Year 4 | F20: Year 5
A21: Sales and marketing | B21: 0.55 | C21: 0.52 | D21: 0.48 | E21: 0.44 | F21: 0.4
A22: Research and development | B22: 0.3 | C22: 0.28 | D22: 0.26 | E22: 0.24 | F22: 0.22
A23: General and administrative | B23: 0.18 | C23: 0.16 | D23: 0.15 | E23: 0.14 | F23: 0.13
A25: Transaction assumptions
A26: Total capital raised (USD millions) | B26: 20
A27: Existing debt refinanced at close (USD millions) | B27: 3
A28: Entry ARR multiple (pre-money) | B28: 8
A29: Exit ARR multiple | B29: 7
A30: Minimum cash covenant (USD millions) | B30: 5
A32: Growth equity case
A33: New equity invested (USD millions) | B33: 20
A35: Private credit case
A36: Principal (USD millions) | B36: 20
A37: Cash interest rate | B37: 0.115
A38: PIK interest rate | B38: 0
A39: Original issue discount | B39: 0.02
A40: Maturity (years) | B40: 5
A41: Interest only period (years) | B41: 3
A42: Annual amortisation (% of original principal) | B42: 0.05
A44: Blended capital case
A45: Equity component (USD millions) | B45: 8
A46: Debt component (USD millions) | B46: 12
...

Sheet Historical Financials
A1: Historical Financials
A2: Illustrative three year history for Northstar Workflow Systems, ending at the model start point.
A3: All figures are hypothetical and illustrative.
A5: Line item (USD millions) | B5: Year -3 | C5: Year -2 | D5: Year -1 | E5: Year 0
A6: Ending ARR | B6: 4.9 | C6: 6.9 | D6: 9.4 | E6: =Assumptions!$B$6 -> 12
A7: ARR growth | B7: n/a | C7: =C6/B6-1 -> 0.40816327 | D7: =D6/C6-1 -> 0.36231884 | E7: =E6/D6-1 -> 0.27659574
A8: Revenue | B8: =B6*0.85 -> 4.165 | C8: =(B6+C6)/2 -> 5.9 | D8: =(C6+D6)/2 -> 8.15 | E8: =(D6+E6)/2 -> 10.7
A9: Gross profit | B9: =B8*Assumptions!$B$11 -> 3.2487 | C9: =C8*Assumptions!$B$11 -> 4.602 | D9: =D8*Assumptions!$B$11 -> 6.357 | E9: =E8*Assumptions!$B$11 -> 8.346
A10: Total operating expenses | B10: 5.4 | C10: 7.3 | D10: 9.6 | E10: 12.7
A11: EBITDA | B11: =B9-B10 -> -2.1513 | C11: =C9-C10 -> -2.698 | D11: =D9-D10 -> -3.243 | E11: =E9-E10 -> -4.354
A12: Cash balance | B12: 6.2 | C12: 9.8 | D12: 7.1 | E12: =Assumptions!$B$14 -> 8
A13: Customer count | B13: 118 | C13: 156 | D13: 199 | E13: =Assumptions!$B$16 -> 240
A15: History is illustrative and is provided so the forecast has a visible starting trajectory. Year 0 ARR, cash, and customer count link to the Assumptions sheet, so the history and the forecast always join.
A17: All figures are hypothetical and illustrative.

Sheet Operating Forecast
A1: Operating Forecast
A2: Five year base case. Churn and expansion are set by retention; New ARR is the residual required to hit the growth target.
A3: All figures are hypothetical and illustrative.
A5: Line item (USD millions) | B5: Year 1 | C5: Year 2 | D5: Year 3 | E5: Year 4 | F5: Year 5
A6: ARR bridge
A7: Beginning ARR | B7: =Assumptions!$B$6 -> 12 | C7: =B12 -> 15.6 | D7: =C12 -> 19.968 | E7: =D12 -> 25.15968 | F7: =E12 -> 31.198003
A8: Growth rate | B8: =MAX(0,Assumptions!$B$7-Assumptions!$B$8*0) -> 0.3 | C8: =MAX(0,Assumptions!$B$7-Assumptions!$B$8*1) -> 0.28 | D8: =MAX(0,Assumptions!$B$7-Assumptions!$B$8*2) -> 0.26 | E8: =MAX(0,Assumptions!$B$7-Assumptions!$B$8*3) -> 0.24 | F8: =MAX(0,Assumptions!$B$7-Assumptions!$B$8*4) -> 0.22
A9: New ARR | B9: =B7*(1+B8)-B7*Assumptions!$B$9 -> 2.4 | C9: =C7*(1+C8)-C7*Assumptions!$B$9 -> 2.808 | D9: =D7*(1+D8)-D7*Assumptions!$B$9 -> 3.19488 | E9: =E7*(1+E8)-E7*Assumptions!$B$9 -> 3.5223552 | F9: =F7*(1+F8)-F7*Assumptions!$B$9 -> 3.7437604
A10: Expansion ARR | B10: =B7*(Assumptions!$B$9-Assumptions!$B$10) -> 2.64 | C10: =C7*(Assumptions!$B$9-Assumptions!$B$10) -> 3.432 | D10: =D7*(Assumptions!$B$9-Assumptions!$B$10) -> 4.39296 | E10: =E7*(Assumptions!$B$9-Assumptions!$B$10) -> 5.5351296 | F10: =F7*(Assumptions!$B$9-Assumptions!$B$10) -> 6.8635607
A11: Churned ARR | B11: =-B7*(1-Assumptions!$B$10) -> -1.44 | C11: =-C7*(1-Assumptions!$B$10) -> -1.872 | D11: =-D7*(1-Assumptions!$B$10) -> -2.39616 | E11: =-E7*(1-Assumptions!$B$10) -> -3.0191616 | F11: =-F7*(1-Assumptions!$B$10) -> -3.7437604
A12: Ending ARR | B12: =B7+B9+B10+B11 -> 15.6 | C12: =C7+C9+C10+C11 -> 19.968 | D12: =D7+D9+D10+D11 -> 25.15968 | E12: =E7+E9+E10+E11 -> 31.198003 | F12: =F7+F9+F10+F11 -> 38.061564
A14: Income statement
A15: Revenue | B15: =(B7+B12)/2 -> 13.8 | C15: =(C7+C12)/2 -> 17.784 | D15: =(D7+D12)/2 -> 22.56384 | E15: =(E7+E12)/2 -> 28.178842 | F15: =(F7+F12)/2 -> 34.629784
A16: Gross profit | B16: =B15*Assumptions!$B$11 -> 10.764 | C16: =C15*Assumptions!$B$11 -> 13.87152 | D16: =D15*Assumptions!$B$11 -> 17.599795 | E16: =E15*Assumptions!$B$11 -> 21.979496 | F16: =F15*Assumptions!$B$11 -> 27.011231
A17: Gross margin | B17: =B16/B15 -> 0.78 | C17: =C16/C15 -> 0.78 | D17: =D16/D15 -> 0.78 | E17: =E16/E15 -> 0.78 | F17: =F16/F15 -> 0.78
A18: Sales and marketing | B18: =-B15*Assumptions!B$21 -> -7.59 | C18: =-C15*Assumptions!C$21 -> -9.24768 | D18: =-D15*Assumptions!D$21 -> -10.830643 | E18: =-E15*Assumptions!E$21 -> -12.39869 | F18: =-F15*Assumptions!F$21 -> -13.851913
A19: Research and development | B19: =-B15*Assumptions!B$22 -> -4.14 | C19: =-C15*Assumptions!C$22 -> -4.97952 | D19: =-D15*Assumptions!D$22 -> -5.8665984 | E19: =-E15*Assumptions!E$22 -> -6.762922 | F19: =-F15*Assumptions!F$22 -> -7.6185524
A20: General and administrative | B20: =-B15*Assumptions!B$23 -> -2.484 | C20: =-C15*Assumptions!C$23 -> -2.84544 | D20: =-D15*Assumptions!D$23 -> -3.384576 | E20: =-E15*Assumptions!E$23 -> -3.9450378 | F20: =-F15*Assumptions!F$23 -> -4.5018719
A21: Total operating expenses | B21: =SUM(B18:B20) -> -14.214 | C21: =SUM(C18:C20) -> -17.07264 | D21: =SUM(D18:D20) -> -20.081818 | E21: =SUM(E18:E20) -> -23.10665 | F21: =SUM(F18:F20) -> -25.972338
A22: EBITDA | B22: =B16+B21 -> -3.45 | C22: =C16+C21 -> -3.20112 | D22: =D16+D21 -> -2.4820224 | E22: =E16+E21 -> -1.1271537 | F22: =F16+F21 -> 1.0388935
A23: EBITDA margin | B23: =B22/B15 -> -0.25 | C23: =C22/C15 -> -0.18 | D23: =D22/D15 -> -0.11 | E23: =E22/E15 -> -0.04 | F23: =F22/F15 -> 0.03
A25: Cash flow
A26: Capital expenditure | B26: =-B15*Assumptions!$B$12 -> -0.276 | C26: =-C15*Assumptions!$B$12 -> -0.35568 | D26: =-D15*Assumptions!$B$12 -> -0.4512768 | E26: =-E15*Assumptions!$B$12 -> -0.56357683 | F26: =-F15*Assumptions!$B$12 -> -0.69259567
A27: Deferred revenue benefit | B27: =(B12-B7)*Assumptions!$B$13 -> 0.36 | C27: =(C12-C7)*Assumptions!$B$13 -> 0.4368 | D27: =(D12-D7)*Assumptions!$B$13 -> 0.519168 | E27: =(E12-E7)*Assumptions!$B$13 -> 0.60383232 | F27: =(F12-F7)*Assumptions!$B$13 -> 0.68635607
A28: Unlevered free cash flow | B28: =B22+B26+B27 -> -3.366 | C28: =C22+C26+C27 -> -3.12 | D28: =D22+D26+D27 -> -2.4141312 | E28: =E22+E26+E27 -> -1.0868982 | F28: =F22+F26+F27 -> 1.0326539
A30: Customers
A31: Beginning customers | B31: =Assumptions!$B$16 -> 240 | C31: =B34 -> 252.93913 | D31: =C34 -> 262.17691 | E31: =D34 -> 267.19247 | F31: =E34 -> 267.65715
A32: New customers | B32: =B9/((B7/B31)*Assumptions!$B$17) -> 41.73913 | C32: =C9/((C7/C31)*Assumptions!$B$17) -> 39.590473 | D32: =D9/((D7/D31)*Assumptions!$B$17) -> 36.476787 | E32: =E9/((E7/E31)*Assumptions!$B$17) -> 32.527778 | F32: =F9/((F7/F31)*Assumptions!$B$17) -> 27.929442
A33: Churned customers | B33: =-B31*(1-Assumptions!$B$10) -> -28.8 | C33: =-C31*(1-Assumptions!$B$10) -> -30.352696 | D33: =-D31*(1-Assumptions!$B$10) -> -31.461229 | E33: =-E31*(1-Assumptions!$B$10) -> -32.063096 | F33: =-F31*(1-Assumptions!$B$10) -> -32.118858
A34: Ending customers | B34: =B31+B32+B33 -> 252.93913 | C34: =C31+C32+C33 -> 262.17691 | D34: =D31+D32+D33 -> 267.19247 | E34: =E31+E32+E33 -> 267.65715 | F34: =F31+F32+F33 -> 263.46773
A36: All figures are hypothetical and illustrative.

Sheet SaaS Metrics
A1: SaaS Metrics
A2: The metrics a growth capital or private credit investor tests first. All derived from the Operating Forecast.
A3: All figures are hypothetical and illustrative.
A5: Metric | B5: Year 1 | C5: Year 2 | D5: Year 3 | E5: Year 4 | F5: Year 5
A6: ARR growth | B6: ='Operating Forecast'!B8 -> 0.3 | C6: ='Operating Forecast'!C8 -> 0.28 | D6: ='Operating Forecast'!D8 -> 0.26 | E6: ='Operating Forecast'!E8 -> 0.24 | F6: ='Operating Forecast'!F8 -> 0.22
A7: Net revenue retention | B7: =Assumptions!$B$9 -> 1.1 | C7: =Assumptions!$B$9 -> 1.1 | D7: =Assumptions!$B$9 -> 1.1 | E7: =Assumptions!$B$9 -> 1.1 | F7: =Assumptions!$B$9 -> 1.1
A8: Gross retention | B8: =Assumptions!$B$10 -> 0.88 | C8: =Assumptions!$B$10 -> 0.88 | D8: =Assumptions!$B$10 -> 0.88 | E8: =Assumptions!$B$10 -> 0.88 | F8: =Assumptions!$B$10 -> 0.88
A9: Gross margin | B9: ='Operating Forecast'!B17 -> 0.78 | C9: ='Operating Forecast'!C17 -> 0.78 | D9: ='Operating Forecast'!D17 -> 0.78 | E9: ='Operating Forecast'!E17 -> 0.78 | F9: ='Operating Forecast'!F17 -> 0.78
A10: CAC payback (months) | B10: =-'Operating Forecast'!B18/(('Operating Forecast'!B9+'Operating Forecast'!B10)*Assumptions!$B$11)*12 -> 23.168498 | C10: =-'Operating Forecast'!C18/(('Operating Forecast'!C9+'Operating Forecast'!C10)*Assumptions!$B$11)*12 -> 22.8 | D10: =-'Operating Forecast'!D18/(('Operating Forecast'!D9+'Operating Forecast'!D10)*Assumptions!$B$11)*12 -> 21.959514 | E10: =-'Operating Forecast'!E18/(('Operating Forecast'!E9+'Operating Forecast'!E10)*Assumptions!$B$11)*12 -> 21.059829 | F10: =-'Operating Forecast'!F18/(('Operating Forecast'!F9+'Operating Forecast'!F10)*Assumptions!$B$11)*12 -> 20.090498
A11: Burn multiple | B11: =IF('Operating Forecast'!B28>=0,"n/a",-'Operating Forecast'!B28/('Operating Forecast'!B12-'Operating Forecast'!B7)) -> 0.935 | C11: =IF('Operating Forecast'!C28>=0,"n/a",-'Operating Forecast'!C28/('Operating Forecast'!C12-'Operating Forecast'!C7)) -> 0.71428571 | D11: =IF('Operating Forecast'!D28>=0,"n/a",-'Operating Forecast'!D28/('Operating Forecast'!D12-'Operating Forecast'!D7)) -> 0.465 | E11: =IF('Operating Forecast'!E28>=0,"n/a",-'Operating Forecast'!E28/('Operating Forecast'!E12-'Operating Forecast'!E7)) -> 0.18 | F11: =IF('Operating Forecast'!F28>=0,"n/a",-'Operating Forecast'!F28/('Operating Forecast'!F12-'Operating Forecast'!F7)) -> n/a
A12: Rule of 40 | B12: ='Operating Forecast'!B8*100+'Operating Forecast'!B23*100 -> 5 | C12: ='Operating Forecast'!C8*100+'Operating Forecast'!C23*100 -> 10 | D12: ='Operating Forecast'!D8*100+'Operating Forecast'!D23*100 -> 15 | E12: ='Operating Forecast'!E8*100+'Operating Forecast'!E23*100 -> 20 | F12: ='Operating Forecast'!F8*100+'Operating Forecast'!F23*100 -> 25
A13: Customer count | B13: ='Operating Forecast'!B34 -> 252.93913 | C13: ='Operating Forecast'!C34 -> 262.17691 | D13: ='Operating Forecast'!D34 -> 267.19247 | E13: ='Operating Forecast'!E34 -> 267.65715 | F13: ='Operating Forecast'!F34 -> 263.46773
A14: Average contract value (USD thousands) | B14: ='Operating Forecast'!B12/'Operating Forecast'!B34*1000 -> 61.674917 | C14: ='Operating Forecast'!C12/'Operating Forecast'!C34*1000 -> 76.162314 | D14: ='Operating Forecast'!D12/'Operating Forecast'!D34*1000 -> 94.163134 | E14: ='Operating Forecast'!E12/'Operating Forecast'!E34*1000 -> 116.55957 | F14: ='Operating Forecast'!F12/'Operating Forecast'!F34*1000 -> 144.46385
A15: Revenue per customer (USD thousands) | B15: ='Operating Forecast'!B15/'Operating Forecast'!B34*1000 -> 54.558581 | C15: ='Operating Forecast'!C15/'Operating Forecast'!C34*1000 -> 67.832061 | D15: ='Operating Forecast'!D15/'Operating Forecast'!D34*1000 -> 84.44789 | E15: ='Operating Forecast'!E15/'Operating Forecast'!E34*1000 -> 105.27962 | F15: ='Operating Forecast'!F15/'Operating Forecast'!F34*1000 -> 131.43842
A17: Where this case is strong: net revenue retention above 100 percent means the installed base grows without new logos, and the burn multiple improves every year. Where it is weak: Rule of 40 never reaches 40 inside the forecast, and gross retention of 88 percent means 12 percent of the base is lost annually. Gross retention is the single assumption most worth challenging in diligence.
A19: All figures are hypothetical and illustrative.

Sheet Capital Structures
A1: Capital Structures
A2: The same capital requirement under three structures. The operating forecast is identical in every case.
A3: All figures are hypothetical and illustrative.
A5: Term | B5: Growth equity | C5: Private credit | D5: Blended capital
A6: Total capital raised | B6: =Assumptions!$B$26 -> 20 | C6: =Assumptions!$B$26 -> 20 | D6: =Assumptions!$B$26 -> 20
A7: Equity component | B7: =Assumptions!$B$33 -> 20 | C7: =0 -> 0 | D7: =Assumptions!$B$45 -> 8
A8: Debt component | B8: =0 -> 0 | C8: =Assumptions!$B$36 -> 20 | D8: =Assumptions!$B$46 -> 12
A9: Original issue discount rate | B9: =0 -> 0 | C9: =Assumptions!$B$39 -> 0.02 | D9: =Assumptions!$B$49 -> 0.015
A10: Original issue discount cost | B10: =0 -> 0 | C10: =C8*C9 -> 0.4 | D10: =D8*D9 -> 0.18
A11: Net proceeds at close | B11: =B7+B8-B10 -> 20 | C11: =C7+C8-C10 -> 19.6 | D11: =D7+D8-D10 -> 19.82
A12: Less existing debt refinanced | B12: =-Assumptions!$B$27 -> -3 | C12: =-Assumptions!$B$27 -> -3 | D12: =-Assumptions!$B$27 -> -3
A13: Cash at close | B13: =Assumptions!$B$14+B11+B12 -> 25 | C13: =Assumptions!$B$14+C11+C12 -> 24.6 | D13: =Assumptions!$B$14+D11+D12 -> 24.82
A15: Ownership
A16: Pre-money valuation | B16: =Assumptions!$B$6*Assumptions!$B$28 -> 96 | C16: =Assumptions!$B$6*Assumptions!$B$28 -> 96 | D16: =Assumptions!$B$6*Assumptions!$B$28 -> 96
A17: Post-money valuation | B17: =B16+B7 -> 116 | C17: =C16 -> 96 | D17: =D16+D7 -> 104
A18: Investor ownership | B18: =B7/B17 -> 0.17241379 | C18: =0 -> 0 | D18: =D7/D17 -> 0.076923077
A19: Founder and existing holder dilution | B19: =B18 -> 0.17241379 | C19: =C18 -> 0 | D19: =D18 -> 0.076923077
A21: Debt terms
A22: Cash interest rate | B22: =0 -> 0 | C22: =Assumptions!$B$37 -> 0.115 | D22: =Assumptions!$B$47 -> 0.11
A23: PIK interest rate | B23: =0 -> 0 | C23: =Assumptions!$B$38 -> 0 | D23: =Assumptions!$B$48 -> 0
A24: Maturity (years) | B24: =0 -> 0 | C24: =Assumptions!$B$40 -> 5 | D24: =Assumptions!$B$50 -> 5
A25: Interest only period (years) | B25: =0 -> 0 | C25: =Assumptions!$B$41 -> 3 | D25: =Assumptions!$B$51 -> 3
A26: Annual amortisation (% of principal) | B26: =0 -> 0 | C26: =Assumptions!$B$42 -> 0.05 | D26: =Assumptions!$B$52 -> 0.05
A28: Uses are held constant across all structures. USD 3.0 million refinances existing debt. Product development, enterprise sales hiring, international expansion, and working capital are embedded in the operating forecast and therefore in cumulative cash burn. Any residual capital is a liquidity and strategic reserve, not a separately modeled acquisition spend.
A30: All figures are hypothetical and illustrative.
A32: Capital sizing bridge - selected blend
A33: Use / requirement | B33: Formula basis | C33: USD millions | D33: Interpretation
A34: Existing debt refinanced | B34: At close | C34: =Assumptions!B27 -> 3 | D34: Required
A35: Base case cumulative operating burn | B35: Five-year unlevered FCF | C35: =-SUM('Operating Forecast'!B28:F28) -> 8.9543755 | D35: Required
A36: Base case debt service | B36: Cash interest + amortisation | C36: =SUM('Blended Capital Case'!B11:F11) -> 7.734 | D36: Required
A37: Minimum ending cash | B37: Liquidity covenant | C37: =Assumptions!B30 -> 5 | D37: Required
A38: Less beginning cash | B38: Existing liquidity | C38: =-Assumptions!B14 -> -8 | D38: Funding source
A39: OID / financing friction | B39: Selected facility OID | C39: =D10 -> 0.18 | D39: Required
A40: Base case gross capital required | B40: Formula-derived minimum | C40: =SUM(C34:C39) -> 16.868375 | D40: Sizing output
A41: Gross capital raised | B41: Selected capital plan | C41: =Assumptions!B26 -> 20 | D41: Plan
A42: Base case excess headroom | B42: Raised less required | C42: =C41-C40 -> 3.1316245 | D42: Headroom
A43: Downside gross capital required | B43: Downside burn substituted | C43: =Assumptions!B27-SUM('Downside Case'!B17:F17)+SUM('Blended Capital Case'!B11:F11)+Assumptions!B30-Assumptions!B14+D10 -> 24.556325 | D43: Stress sizing
A44: Downside funding shortfall | B44: Required less raised | C44: =MAX(0,C43-C41) -> 4.5563251 | D44: Stress gap

Sheet Growth Equity Case
A1: Growth Equity Case
A2: USD 20 million of primary equity. No leverage. The safest structure and the most expensive in ownership terms.
A3: All figures are hypothetical and illustrative.
A5: Cash roll forward
A6: Line item (USD millions) | B6: Year 1 | C6: Year 2 | D6: Year 3 | E6: Year 4 | F6: Year 5
A7: Opening cash | B7: ='Capital Structures'!B13 -> 25 | C7: =B11 -> 21.634 | D7: =C11 -> 18.514 | E7: =D11 -> 16.099869 | F7: =E11 -> 15.012971
A8: Unlevered free cash flow | B8: ='Operating Forecast'!B28 -> -3.366 | C8: ='Operating Forecast'!C28 -> -3.12 | D8: ='Operating Forecast'!D28 -> -2.4141312 | E8: ='Operating Forecast'!E28 -> -1.0868982 | F8: ='Operating Forecast'!F28 -> 1.0326539
A9: Cash interest | B9: =0 -> 0 | C9: =0 -> 0 | D9: =0 -> 0 | E9: =0 -> 0 | F9: =0 -> 0
A10: Amortisation | B10: =0 -> 0 | C10: =0 -> 0 | D10: =0 -> 0 | E10: =0 -> 0 | F10: =0 -> 0
A11: Closing cash | B11: =SUM(B7:B10) -> 21.634 | C11: =SUM(C7:C10) -> 18.514 | D11: =SUM(D7:D10) -> 16.099869 | E11: =SUM(E7:E10) -> 15.012971 | F11: =SUM(F7:F10) -> 16.045625
A12: Minimum cash covenant | B12: =Assumptions!$B$30 -> 5 | C12: =Assumptions!$B$30 -> 5 | D12: =Assumptions!$B$30 -> 5 | E12: =Assumptions!$B$30 -> 5 | F12: =Assumptions!$B$30 -> 5
A13: Covenant headroom | B13: =B11-B12 -> 16.634 | C13: =C11-C12 -> 13.514 | D13: =D11-D12 -> 11.099869 | E13: =E11-E12 -> 10.012971 | F13: =F11-F12 -> 11.045625
A14: Covenant status | B14: =IF(B11<B12,"BREACH","Headroom") -> Headroom | C14: =IF(C11<C12,"BREACH","Headroom") -> Headroom | D14: =IF(D11<D12,"BREACH","Headroom") -> Headroom | E14: =IF(E11<E12,"BREACH","Headroom") -> Headroom | F14: =IF(F11<F12,"BREACH","Headroom") -> Headroom
A15: Runway (months at current burn) | B15: =IF(B11-B7>=0,"cash generative",B11/(B7-B11)*12) -> 77.12656 | C15: =IF(C11-C7>=0,"cash generative",C11/(C7-C11)*12) -> 71.207692 | D15: =IF(D11-D7>=0,"cash generative",D11/(D7-D11)*12) -> 80.028138 | E15: =IF(E11-E7>=0,"cash generative",E11/(E7-E11)*12) -> 165.75209 | F15: =IF(F11-F7>=0,"cash generative",F11/(F7-F11)*12) -> cash generative
A17: Exit and returns
A18: Year 5 ending ARR | B18: ='Operating Forecast'!F12 -> 38.061564
A19: Exit ARR multiple | B19: =Assumptions!$B$29 -> 7
A20: Exit enterprise value | B20: =B18*B19 -> 266.43095
A21: Plus year 5 cash | B21: =F11 -> 16.045625
A22: Less year 5 debt | B22: =0 -> 0
A23: Exit equity value | B23: =B20+B21+B22 -> 282.47657
A24: Equity investor ownership | B24: ='Capital Structures'!B18 -> 0.17241379
A25: Equity invested | B25: =Assumptions!$B$33 -> 20
A26: Equity investor proceeds at exit | B26: =B23*B24 -> 48.702857
A27: Equity investor MOIC | B27: =IF(B25=0,"n/a",B26/B25) -> 2.4351429
A28: Equity investor IRR | B28: =IF(B25=0,"n/a",(B26/B25)^(1/5)-1) -> 0.19482662
A30: All figures are hypothetical and illustrative.

Sheet Private Credit Case
A1: Private Credit Case
A2: USD 20 million senior secured. No dilution, and the company cannot service it from operating cash flow.
A3: All figures are hypothetical and illustrative.
A5: Debt schedule
A6: Line item (USD millions) | B6: Year 1 | C6: Year 2 | D6: Year 3 | E6: Year 4 | F6: Year 5
A7: Opening balance | B7: =Assumptions!$B$36 -> 20 | C7: =B12 -> 20 | D7: =C12 -> 20 | E7: =D12 -> 20 | F7: =E12 -> 19
A8: Cash interest | B8: =B7*Assumptions!$B$37 -> 2.3 | C8: =C7*Assumptions!$B$37 -> 2.3 | D8: =D7*Assumptions!$B$37 -> 2.3 | E8: =E7*Assumptions!$B$37 -> 2.3 | F8: =F7*Assumptions!$B$37 -> 2.185
A9: PIK interest | B9: =B7*Assumptions!$B$38 -> 0 | C9: =C7*Assumptions!$B$38 -> 0 | D9: =D7*Assumptions!$B$38 -> 0 | E9: =E7*Assumptions!$B$38 -> 0 | F9: =F7*Assumptions!$B$38 -> 0
A10: Amortisation | B10: =IF(1>Assumptions!$B$41,Assumptions!$B$36*Assumptions!$B$42,0) -> 0 | C10: =IF(2>Assumptions!$B$41,Assumptions!$B$36*Assumptions!$B$42,0) -> 0 | D10: =IF(3>Assumptions!$B$41,Assumptions!$B$36*Assumptions!$B$42,0) -> 0 | E10: =IF(4>Assumptions!$B$41,Assumptions!$B$36*Assumptions!$B$42,0) -> 1 | F10: =IF(5>Assumptions!$B$41,Assumptions!$B$36*Assumptions!$B$42,0) -> 1
A11: Debt service | B11: =B8+B10 -> 2.3 | C11: =C8+C10 -> 2.3 | D11: =D8+D10 -> 2.3 | E11: =E8+E10 -> 3.3 | F11: =F8+F10 -> 3.185
A12: Closing balance | B12: =B7+B9-B10 -> 20 | C12: =C7+C9-C10 -> 20 | D12: =D7+D9-D10 -> 20 | E12: =E7+E9-E10 -> 19 | F12: =F7+F9-F10 -> 18
A13: Debt to ending ARR | B13: =B12/'Operating Forecast'!B12 -> 1.2820513 | C13: =C12/'Operating Forecast'!C12 -> 1.0016026 | D13: =D12/'Operating Forecast'!D12 -> 0.79492267 | E13: =E12/'Operating Forecast'!E12 -> 0.60901334 | F13: =F12/'Operating Forecast'!F12 -> 0.47291803
A14: Interest coverage (EBITDA / cash interest) | B14: =IF(B8=0,"n/a",'Operating Forecast'!B22/B8) -> -1.5 | C14: =IF(C8=0,"n/a",'Operating Forecast'!C22/C8) -> -1.3917913 | D14: =IF(D8=0,"n/a",'Operating Forecast'!D22/D8) -> -1.0791402 | E14: =IF(E8=0,"n/a",'Operating Forecast'!E22/E8) -> -0.49006681 | F14: =IF(F8=0,"n/a",'Operating Forecast'!F22/F8) -> 0.47546614
A15: Debt service coverage ratio | B15: =IF(B11=0,"n/a",('Operating Forecast'!B22+'Operating Forecast'!B26)/B11) -> -1.62 | C15: =IF(C11=0,"n/a",('Operating Forecast'!C22+'Operating Forecast'!C26)/C11) -> -1.5464348 | D15: =IF(D11=0,"n/a",('Operating Forecast'!D22+'Operating Forecast'!D26)/D11) -> -1.2753475 | E15: =IF(E11=0,"n/a",('Operating Forecast'!E22+'Operating Forecast'!E26)/E11) -> -0.51234257 | F15: =IF(F11=0,"n/a",('Operating Forecast'!F22+'Operating Forecast'!F26)/F11) -> 0.10872773
A17: Cash roll forward
A18: Line item (USD millions) | B18: Year 1 | C18: Year 2 | D18: Year 3 | E18: Year 4 | F18: Year 5
A19: Opening cash | B19: ='Capital Structures'!C13 -> 24.6 | C19: =B23 -> 18.934 | D19: =C23 -> 13.514 | E19: =D23 -> 8.7998688 | F19: =E23 -> 4.4129706
A20: Unlevered free cash flow | B20: ='Operating Forecast'!B28 -> -3.366 | C20: ='Operating Forecast'!C28 -> -3.12 | D20: ='Operating Forecast'!D28 -> -2.4141312 | E20: ='Operating Forecast'!E28 -> -1.0868982 | F20: ='Operating Forecast'!F28 -> 1.0326539
A21: Cash interest | B21: =-B8 -> -2.3 | C21: =-C8 -> -2.3 | D21: =-D8 -> -2.3 | E21: =-E8 -> -2.3 | F21: =-F8 -> -2.185
A22: Amortisation | B22: =-B10 -> 0 | C22: =-C10 -> 0 | D22: =-D10 -> 0 | E22: =-E10 -> -1 | F22: =-F10 -> -1
A23: Closing cash | B23: =SUM(B19:B22) -> 18.934 | C23: =SUM(C19:C22) -> 13.514 | D23: =SUM(D19:D22) -> 8.7998688 | E23: =SUM(E19:E22) -> 4.4129706 | F23: =SUM(F19:F22) -> 2.2606245
A24: Minimum cash covenant | B24: =Assumptions!$B$30 -> 5 | C24: =Assumptions!$B$30 -> 5 | D24: =Assumptions!$B$30 -> 5 | E24: =Assumptions!$B$30 -> 5 | F24: =Assumptions!$B$30 -> 5
A25: Covenant headroom | B25: =B23-B24 -> 13.934 | C25: =C23-C24 -> 8.514 | D25: =D23-D24 -> 3.7998688 | E25: =E23-E24 -> -0.58702938 | F25: =F23-F24 -> -2.7393755
A26: Covenant status | B26: =IF(B23<B24,"BREACH","Headroom") -> Headroom | C26: =IF(C23<C24,"BREACH","Headroom") -> Headroom | D26: =IF(D23<D24,"BREACH","Headroom") -> Headroom | E26: =IF(E23<E24,"BREACH","Headroom") -> BREACH | F26: =IF(F23<F24,"BREACH","Headroom") -> BREACH
A27: Runway (months at current burn) | B27: =IF(B23-B19>=0,"cash generative",B23/(B19-B23)*12) -> 40.100247 | C27: =IF(C23-C19>=0,"cash generative",C23/(C19-C23)*12) -> 29.920295 | D27: =IF(D23-D19>=0,"cash generative",D23/(D19-D23)*12) -> 22.4004 | E27: =IF(E23-E19>=0,"cash generative",E23/(E19-E23)*12) -> 12.071319 | F27: =IF(F23-F19>=0,"cash generative",F23/(F19-F23)*12) -> 12.603686
A29: Exit and returns
A30: Year 5 ending ARR | B30: ='Operating Forecast'!F12 -> 38.061564
A31: Exit ARR multiple | B31: =Assumptions!$B$29 -> 7
A32: Exit enterprise value | B32: =B30*B31 -> 266.43095
A33: Plus year 5 cash | B33: =F23 -> 2.2606245
A34: Less year 5 debt | B34: =-F12 -> -18
A35: Exit equity value | B35: =B32+B33+B34 -> 250.69157
A36: Equity investor ownership | B36: ='Capital Structures'!C18 -> 0
A37: Equity invested | B37: =0 -> 0
A38: Equity investor proceeds at exit | B38: =B35*B36 -> 0
A39: Equity investor MOIC | B39: =IF(B37=0,"n/a",B38/B37) -> n/a
A40: Equity investor IRR | B40: =IF(B37=0,"n/a",(B38/B37)^(1/5)-1) -> n/a
A42: Debt investor return
A43: Principal advanced | B43: =Assumptions!$B$36 -> 20
A44: Less original issue discount | B44: =-Assumptions!$B$36*Assumptions!$B$39 -> -0.4
...

Sheet Blended Capital Case
A1: Blended Capital Case
A2: USD 8 million of primary equity alongside a USD 12 million senior secured facility. The recommended structure.
A3: All figures are hypothetical and illustrative.
A5: Debt schedule
A6: Line item (USD millions) | B6: Year 1 | C6: Year 2 | D6: Year 3 | E6: Year 4 | F6: Year 5
A7: Opening balance | B7: =Assumptions!$B$46 -> 12 | C7: =B12 -> 12 | D7: =C12 -> 12 | E7: =D12 -> 12 | F7: =E12 -> 11.4
A8: Cash interest | B8: =B7*Assumptions!$B$47 -> 1.32 | C8: =C7*Assumptions!$B$47 -> 1.32 | D8: =D7*Assumptions!$B$47 -> 1.32 | E8: =E7*Assumptions!$B$47 -> 1.32 | F8: =F7*Assumptions!$B$47 -> 1.254
A9: PIK interest | B9: =B7*Assumptions!$B$48 -> 0 | C9: =C7*Assumptions!$B$48 -> 0 | D9: =D7*Assumptions!$B$48 -> 0 | E9: =E7*Assumptions!$B$48 -> 0 | F9: =F7*Assumptions!$B$48 -> 0
A10: Amortisation | B10: =IF(1>Assumptions!$B$51,Assumptions!$B$46*Assumptions!$B$52,0) -> 0 | C10: =IF(2>Assumptions!$B$51,Assumptions!$B$46*Assumptions!$B$52,0) -> 0 | D10: =IF(3>Assumptions!$B$51,Assumptions!$B$46*Assumptions!$B$52,0) -> 0 | E10: =IF(4>Assumptions!$B$51,Assumptions!$B$46*Assumptions!$B$52,0) -> 0.6 | F10: =IF(5>Assumptions!$B$51,Assumptions!$B$46*Assumptions!$B$52,0) -> 0.6
A11: Debt service | B11: =B8+B10 -> 1.32 | C11: =C8+C10 -> 1.32 | D11: =D8+D10 -> 1.32 | E11: =E8+E10 -> 1.92 | F11: =F8+F10 -> 1.854
A12: Closing balance | B12: =B7+B9-B10 -> 12 | C12: =C7+C9-C10 -> 12 | D12: =D7+D9-D10 -> 12 | E12: =E7+E9-E10 -> 11.4 | F12: =F7+F9-F10 -> 10.8
A13: Debt to ending ARR | B13: =B12/'Operating Forecast'!B12 -> 0.76923077 | C13: =C12/'Operating Forecast'!C12 -> 0.60096154 | D13: =D12/'Operating Forecast'!D12 -> 0.4769536 | E13: =E12/'Operating Forecast'!E12 -> 0.365408 | F13: =F12/'Operating Forecast'!F12 -> 0.28375082
A14: Interest coverage (EBITDA / cash interest) | B14: =IF(B8=0,"n/a",'Operating Forecast'!B22/B8) -> -2.6136364 | C14: =IF(C8=0,"n/a",'Operating Forecast'!C22/C8) -> -2.4250909 | D14: =IF(D8=0,"n/a",'Operating Forecast'!D22/D8) -> -1.88032 | E14: =IF(E8=0,"n/a",'Operating Forecast'!E22/E8) -> -0.85390429 | F14: =IF(F8=0,"n/a",'Operating Forecast'!F22/F8) -> 0.82846372
A15: Debt service coverage ratio | B15: =IF(B11=0,"n/a",('Operating Forecast'!B22+'Operating Forecast'!B26)/B11) -> -2.8227273 | C15: =IF(C11=0,"n/a",('Operating Forecast'!C22+'Operating Forecast'!C26)/C11) -> -2.6945455 | D15: =IF(D11=0,"n/a",('Operating Forecast'!D22+'Operating Forecast'!D26)/D11) -> -2.2221964 | E15: =IF(E11=0,"n/a",('Operating Forecast'!E22+'Operating Forecast'!E26)/E11) -> -0.8805888 | F15: =IF(F11=0,"n/a",('Operating Forecast'!F22+'Operating Forecast'!F26)/F11) -> 0.18678416
A17: Cash roll forward
A18: Line item (USD millions) | B18: Year 1 | C18: Year 2 | D18: Year 3 | E18: Year 4 | F18: Year 5
A19: Opening cash | B19: ='Capital Structures'!D13 -> 24.82 | C19: =B23 -> 20.134 | D19: =C23 -> 15.694 | E19: =D23 -> 11.959869 | F19: =E23 -> 8.9529706
A20: Unlevered free cash flow | B20: ='Operating Forecast'!B28 -> -3.366 | C20: ='Operating Forecast'!C28 -> -3.12 | D20: ='Operating Forecast'!D28 -> -2.4141312 | E20: ='Operating Forecast'!E28 -> -1.0868982 | F20: ='Operating Forecast'!F28 -> 1.0326539
A21: Cash interest | B21: =-B8 -> -1.32 | C21: =-C8 -> -1.32 | D21: =-D8 -> -1.32 | E21: =-E8 -> -1.32 | F21: =-F8 -> -1.254
A22: Amortisation | B22: =-B10 -> 0 | C22: =-C10 -> 0 | D22: =-D10 -> 0 | E22: =-E10 -> -0.6 | F22: =-F10 -> -0.6
A23: Closing cash | B23: =SUM(B19:B22) -> 20.134 | C23: =SUM(C19:C22) -> 15.694 | D23: =SUM(D19:D22) -> 11.959869 | E23: =SUM(E19:E22) -> 8.9529706 | F23: =SUM(F19:F22) -> 8.1316245
A24: Minimum cash covenant | B24: =Assumptions!$B$30 -> 5 | C24: =Assumptions!$B$30 -> 5 | D24: =Assumptions!$B$30 -> 5 | E24: =Assumptions!$B$30 -> 5 | F24: =Assumptions!$B$30 -> 5
A25: Covenant headroom | B25: =B23-B24 -> 15.134 | C25: =C23-C24 -> 10.694 | D25: =D23-D24 -> 6.9598688 | E25: =E23-E24 -> 3.9529706 | F25: =F23-F24 -> 3.1316245
A26: Covenant status | B26: =IF(B23<B24,"BREACH","Headroom") -> Headroom | C26: =IF(C23<C24,"BREACH","Headroom") -> Headroom | D26: =IF(D23<D24,"BREACH","Headroom") -> Headroom | E26: =IF(E23<E24,"BREACH","Headroom") -> Headroom | F26: =IF(F23<F24,"BREACH","Headroom") -> Headroom
A27: Runway (months at current burn) | B27: =IF(B23-B19>=0,"cash generative",B23/(B19-B23)*12) -> 51.559539 | C27: =IF(C23-C19>=0,"cash generative",C23/(C19-C23)*12) -> 42.416216 | D27: =IF(D23-D19>=0,"cash generative",D23/(D19-D23)*12) -> 38.434221 | E27: =IF(E23-E19>=0,"cash generative",E23/(E19-E23)*12) -> 35.729726 | F27: =IF(F23-F19>=0,"cash generative",F23/(F19-F23)*12) -> 118.80436
A29: Exit and returns
A30: Year 5 ending ARR | B30: ='Operating Forecast'!F12 -> 38.061564
A31: Exit ARR multiple | B31: =Assumptions!$B$29 -> 7
A32: Exit enterprise value | B32: =B30*B31 -> 266.43095
A33: Plus year 5 cash | B33: =F23 -> 8.1316245
A34: Less year 5 debt | B34: =-F12 -> -10.8
A35: Exit equity value | B35: =B32+B33+B34 -> 263.76257
A36: Equity investor ownership | B36: ='Capital Structures'!D18 -> 0.076923077
A37: Equity invested | B37: =Assumptions!$B$45 -> 8
A38: Equity investor proceeds at exit | B38: =B35*B36 -> 20.289429
A39: Equity investor MOIC | B39: =IF(B37=0,"n/a",B38/B37) -> 2.5361786
A40: Equity investor IRR | B40: =IF(B37=0,"n/a",(B38/B37)^(1/5)-1) -> 0.20458088
A42: Debt investor return
A43: Principal advanced | B43: =Assumptions!$B$46 -> 12
A44: Less original issue discount | B44: =-Assumptions!$B$46*Assumptions!$B$49 -> -0.18
...

Sheet Debt Schedule
A1: Debt Schedule
A2: Both debt structures side by side, drawn from the case sheets. Terms are editable on the Assumptions sheet.
A3: All figures are hypothetical and illustrative.
A5: Private credit: USD 20 million facility
A6: Line item (USD millions) | B6: Year 1 | C6: Year 2 | D6: Year 3 | E6: Year 4 | F6: Year 5
A7: Opening balance | B7: ='Private Credit Case'!B7 -> 20 | C7: ='Private Credit Case'!C7 -> 20 | D7: ='Private Credit Case'!D7 -> 20 | E7: ='Private Credit Case'!E7 -> 20 | F7: ='Private Credit Case'!F7 -> 19
A8: Cash interest | B8: ='Private Credit Case'!B8 -> 2.3 | C8: ='Private Credit Case'!C8 -> 2.3 | D8: ='Private Credit Case'!D8 -> 2.3 | E8: ='Private Credit Case'!E8 -> 2.3 | F8: ='Private Credit Case'!F8 -> 2.185
A9: PIK interest | B9: ='Private Credit Case'!B9 -> 0 | C9: ='Private Credit Case'!C9 -> 0 | D9: ='Private Credit Case'!D9 -> 0 | E9: ='Private Credit Case'!E9 -> 0 | F9: ='Private Credit Case'!F9 -> 0
A10: Amortisation | B10: ='Private Credit Case'!B10 -> 0 | C10: ='Private Credit Case'!C10 -> 0 | D10: ='Private Credit Case'!D10 -> 0 | E10: ='Private Credit Case'!E10 -> 1 | F10: ='Private Credit Case'!F10 -> 1
A11: Debt service | B11: ='Private Credit Case'!B11 -> 2.3 | C11: ='Private Credit Case'!C11 -> 2.3 | D11: ='Private Credit Case'!D11 -> 2.3 | E11: ='Private Credit Case'!E11 -> 3.3 | F11: ='Private Credit Case'!F11 -> 3.185
A12: Closing balance | B12: ='Private Credit Case'!B12 -> 20 | C12: ='Private Credit Case'!C12 -> 20 | D12: ='Private Credit Case'!D12 -> 20 | E12: ='Private Credit Case'!E12 -> 19 | F12: ='Private Credit Case'!F12 -> 18
A13: Debt to ending ARR | B13: ='Private Credit Case'!B13 -> 1.2820513 | C13: ='Private Credit Case'!C13 -> 1.0016026 | D13: ='Private Credit Case'!D13 -> 0.79492267 | E13: ='Private Credit Case'!E13 -> 0.60901334 | F13: ='Private Credit Case'!F13 -> 0.47291803
A14: Interest coverage | B14: ='Private Credit Case'!B14 -> -1.5 | C14: ='Private Credit Case'!C14 -> -1.3917913 | D14: ='Private Credit Case'!D14 -> -1.0791402 | E14: ='Private Credit Case'!E14 -> -0.49006681 | F14: ='Private Credit Case'!F14 -> 0.47546614
A15: Debt service coverage ratio | B15: ='Private Credit Case'!B15 -> -1.62 | C15: ='Private Credit Case'!C15 -> -1.5464348 | D15: ='Private Credit Case'!D15 -> -1.2753475 | E15: ='Private Credit Case'!E15 -> -0.51234257 | F15: ='Private Credit Case'!F15 -> 0.10872773
A17: Blended capital: USD 12 million facility
A18: Line item (USD millions) | B18: Year 1 | C18: Year 2 | D18: Year 3 | E18: Year 4 | F18: Year 5
A19: Opening balance | B19: ='Blended Capital Case'!B7 -> 12 | C19: ='Blended Capital Case'!C7 -> 12 | D19: ='Blended Capital Case'!D7 -> 12 | E19: ='Blended Capital Case'!E7 -> 12 | F19: ='Blended Capital Case'!F7 -> 11.4
A20: Cash interest | B20: ='Blended Capital Case'!B8 -> 1.32 | C20: ='Blended Capital Case'!C8 -> 1.32 | D20: ='Blended Capital Case'!D8 -> 1.32 | E20: ='Blended Capital Case'!E8 -> 1.32 | F20: ='Blended Capital Case'!F8 -> 1.254
A21: PIK interest | B21: ='Blended Capital Case'!B9 -> 0 | C21: ='Blended Capital Case'!C9 -> 0 | D21: ='Blended Capital Case'!D9 -> 0 | E21: ='Blended Capital Case'!E9 -> 0 | F21: ='Blended Capital Case'!F9 -> 0
A22: Amortisation | B22: ='Blended Capital Case'!B10 -> 0 | C22: ='Blended Capital Case'!C10 -> 0 | D22: ='Blended Capital Case'!D10 -> 0 | E22: ='Blended Capital Case'!E10 -> 0.6 | F22: ='Blended Capital Case'!F10 -> 0.6
A23: Debt service | B23: ='Blended Capital Case'!B11 -> 1.32 | C23: ='Blended Capital Case'!C11 -> 1.32 | D23: ='Blended Capital Case'!D11 -> 1.32 | E23: ='Blended Capital Case'!E11 -> 1.92 | F23: ='Blended Capital Case'!F11 -> 1.854
A24: Closing balance | B24: ='Blended Capital Case'!B12 -> 12 | C24: ='Blended Capital Case'!C12 -> 12 | D24: ='Blended Capital Case'!D12 -> 12 | E24: ='Blended Capital Case'!E12 -> 11.4 | F24: ='Blended Capital Case'!F12 -> 10.8
A25: Debt to ending ARR | B25: ='Blended Capital Case'!B13 -> 0.76923077 | C25: ='Blended Capital Case'!C13 -> 0.60096154 | D25: ='Blended Capital Case'!D13 -> 0.4769536 | E25: ='Blended Capital Case'!E13 -> 0.365408 | F25: ='Blended Capital Case'!F13 -> 0.28375082
A26: Interest coverage | B26: ='Blended Capital Case'!B14 -> -2.6136364 | C26: ='Blended Capital Case'!C14 -> -2.4250909 | D26: ='Blended Capital Case'!D14 -> -1.88032 | E26: ='Blended Capital Case'!E14 -> -0.85390429 | F26: ='Blended Capital Case'!F14 -> 0.82846372
A27: Debt service coverage ratio | B27: ='Blended Capital Case'!B15 -> -2.8227273 | C27: ='Blended Capital Case'!C15 -> -2.6945455 | D27: ='Blended Capital Case'!D15 -> -2.2221964 | E27: ='Blended Capital Case'!E15 -> -0.8805888 | F27: ='Blended Capital Case'!F15 -> 0.18678416
A29: Interest coverage is EBITDA divided by cash interest and is negative for as long as EBITDA is negative. Debt service coverage is EBITDA less capital expenditure over total debt service. Neither ratio reaches 1.0x on the USD 20 million facility inside the forecast period, which is the arithmetic reason the all debt structure is rejected.
A31: All figures are hypothetical and illustrative.

Sheet Returns Analysis
A1: Returns Analysis
A2: Explicit cash flows and returns for equity and debt investors under each structure.
A3: All figures are hypothetical and illustrative.
A5: Equity investor cash flows (USD millions)
A6: Structure | B6: Close | C6: Year 1 | D6: Year 2 | E6: Year 3 | F6: Year 4 | G6: Year 5
A7: Growth equity | B7: =-'Growth Equity Case'!B25 -> -20 | C7: 0 | D7: 0 | E7: 0 | F7: 0 | G7: ='Growth Equity Case'!B26 -> 48.702857
A8: Blended capital | B8: =-'Blended Capital Case'!B37 -> -8 | C8: 0 | D8: 0 | E8: 0 | F8: 0 | G8: ='Blended Capital Case'!B38 -> 20.289429
A10: Equity investor returns
A11: Metric | B11: Growth equity | C11: Private credit | D11: Blended capital
A12: Equity invested | B12: ='Growth Equity Case'!B25 -> 20 | C12: =0 -> 0 | D12: ='Blended Capital Case'!B37 -> 8
A13: Investor ownership | B13: ='Growth Equity Case'!B24 -> 0.17241379 | C13: =0 -> 0 | D13: ='Blended Capital Case'!B36 -> 0.076923077
A14: Exit equity value | B14: ='Growth Equity Case'!B23 -> 282.47657 | C14: ='Private Credit Case'!B35 -> 250.69157 | D14: ='Blended Capital Case'!B35 -> 263.76257
A15: Equity investor proceeds | B15: ='Growth Equity Case'!B26 -> 48.702857 | C15: =0 -> 0 | D15: ='Blended Capital Case'!B38 -> 20.289429
A16: MOIC | B16: ='Growth Equity Case'!B27 -> 2.4351429 | C16: ="n/a" -> n/a | D16: ='Blended Capital Case'!B39 -> 2.5361786
A17: IRR (5 year hold) | B17: =IRR(B7:G7) -> 0.19482662 | C17: ="n/a" -> n/a | D17: =IRR(B8:G8) -> 0.20458088
A18: Founder and existing holder dilution | B18: ='Capital Structures'!B19 -> 0.17241379 | C18: ='Capital Structures'!C19 -> 0 | D18: ='Capital Structures'!D19 -> 0.076923077
A20: Debt investor returns
A21: Metric | B21: Growth equity | C21: Private credit | D21: Blended capital
A22: Net outlay at close | B22: ="n/a" -> n/a | C22: ='Private Credit Case'!B45 -> 19.6 | D22: ='Blended Capital Case'!B45 -> 11.82
A23: Total received over five years | B23: ="n/a" -> n/a | C23: ='Private Credit Case'!B49 -> 31.385 | D23: ='Blended Capital Case'!B49 -> 18.534
A24: Debt investor MOIC | B24: ="n/a" -> n/a | C24: ='Private Credit Case'!B50 -> 1.6012755 | D24: ='Blended Capital Case'!B50 -> 1.5680203
A26: Debt investor cash flows (USD millions)
A27: Structure | B27: Close | C27: Year 1 | D27: Year 2 | E27: Year 3 | F27: Year 4 | G27: Year 5
A28: Private credit | B28: =-'Private Credit Case'!B45 -> -19.6 | C28: ='Private Credit Case'!B8+'Private Credit Case'!B10 -> 2.3 | D28: ='Private Credit Case'!C8+'Private Credit Case'!C10 -> 2.3 | E28: ='Private Credit Case'!D8+'Private Credit Case'!D10 -> 2.3 | F28: ='Private Credit Case'!E8+'Private Credit Case'!E10 -> 3.3 | G28: ='Private Credit Case'!F8+'Private Credit Case'!F10+'Private Credit Case'!F12 -> 21.185
A29: Blended capital | B29: =-'Blended Capital Case'!B45 -> -11.82 | C29: ='Blended Capital Case'!B8+'Blended Capital Case'!B10 -> 1.32 | D29: ='Blended Capital Case'!C8+'Blended Capital Case'!C10 -> 1.32 | E29: ='Blended Capital Case'!D8+'Blended Capital Case'!D10 -> 1.32 | F29: ='Blended Capital Case'!E8+'Blended Capital Case'!E10 -> 1.92 | G29: ='Blended Capital Case'!F8+'Blended Capital Case'!F10+'Blended Capital Case'!F12 -> 12.654
A30: Debt investor IRR | B30: ="n/a" -> n/a | C30: =IRR(B28:G28) -> 0.12060048 | D30: =IRR(B29:G29) -> 0.11413376
A32: The equity investor MOIC is higher under the blended structure than under all equity, because a smaller cheque is exposed to the same enterprise value appreciation. That is the return argument for the blend. The dilution argument is stronger still, and the covenant argument is what makes the all debt structure unavailable.
A34: All figures are hypothetical and illustrative.
A36: Existing holder value
A37: Metric | B37: Growth equity | C37: Private credit | D37: Selected blend | E37: Notes
A38: Existing holder ownership | B38: =1-'Capital Structures'!B18 -> 0.82758621 | C38: =1-'Capital Structures'!C18 -> 1 | D38: =1-'Capital Structures'!D18 -> 0.92307692 | E38: Post-financing ownership
A39: Exit equity value | B39: ='Growth Equity Case'!B23 -> 282.47657 | C39: ='Private Credit Case'!B35 -> 250.69157 | D39: ='Blended Capital Case'!B35 -> 263.76257 | E39: After cash and debt
A40: Existing holder proceeds | B40: =B38*B39 -> 233.77371 | C40: =C38*C39 -> 250.69157 | D40: =D38*D39 -> 243.47314 | E40: Ownership multiplied by exit equity value
A41: Incremental proceeds versus all equity | B41: =0 -> 0 | C41: =C40-B40 -> 16.917857 | D41: =D40-B40 -> 9.6994286 | E41: Exact value retained, not dilution percentage times a common equity value
A43: Correction to the earlier narrative: the selected blend does not create USD 25 million of incremental value for existing holders. The exact formula-driven difference versus all equity is approximately USD 9.7 million because exit equity value differs across structures after accounting for cash and debt.

Sheet Sensitivities
A1: Sensitivities
A2: Each table moves one driver and holds everything else constant, so the effect is attributable.
A3: All figures are hypothetical and illustrative.
A5: Exit multiple sensitivity, blended capital equity investor
A6: Year five ARR and ending cash are held at the base case. Only the exit ARR multiple moves.
A7: Exit ARR multiple | B7: Enterprise value | C7: Exit equity value | D7: Proceeds | E7: MOIC | F7: IRR
A8: 5 | B8: ='Blended Capital Case'!B30*A8 -> 190.30782 | C8: =B8+'Blended Capital Case'!B33+'Blended Capital Case'!B34 -> 187.63944 | D8: =C8*'Blended Capital Case'!B36 -> 14.433803 | E8: =D8/'Blended Capital Case'!B37 -> 1.8042254 | F8: =E8^(1/5)-1 -> 0.12527368
A9: 6 | B9: ='Blended Capital Case'!B30*A9 -> 228.36938 | C9: =B9+'Blended Capital Case'!B33+'Blended Capital Case'!B34 -> 225.70101 | D9: =C9*'Blended Capital Case'!B36 -> 17.361616 | E9: =D9/'Blended Capital Case'!B37 -> 2.170202 | F9: =E9^(1/5)-1 -> 0.16761598
A10: 7 | B10: ='Blended Capital Case'!B30*A10 -> 266.43095 | C10: =B10+'Blended Capital Case'!B33+'Blended Capital Case'!B34 -> 263.76257 | D10: =C10*'Blended Capital Case'!B36 -> 20.289429 | E10: =D10/'Blended Capital Case'!B37 -> 2.5361786 | F10: =E10^(1/5)-1 -> 0.20458088
A11: 8 | B11: ='Blended Capital Case'!B30*A11 -> 304.49251 | C11: =B11+'Blended Capital Case'!B33+'Blended Capital Case'!B34 -> 301.82414 | D11: =C11*'Blended Capital Case'!B36 -> 23.217241 | E11: =D11/'Blended Capital Case'!B37 -> 2.9021552 | F11: =E11^(1/5)-1 -> 0.23749692
A12: 9 | B12: ='Blended Capital Case'!B30*A12 -> 342.55408 | C12: =B12+'Blended Capital Case'!B33+'Blended Capital Case'!B34 -> 339.8857 | D12: =C12*'Blended Capital Case'!B36 -> 26.145054 | E12: =D12/'Blended Capital Case'!B37 -> 3.2681317 | F12: =E12^(1/5)-1 -> 0.26724303
A14: ARR growth sensitivity
A15: Year one growth varies. The same annual decay applies in later years.
A16: Year 1 ARR growth | B16: Year 5 ending ARR | C16: Exit enterprise value at base multiple
A17: 0.2 | B17: =Assumptions!$B$6*(1+MAX(0,A17-Assumptions!$B$8*0))*(1+MAX(0,A17-Assumptions!$B$8*1))*(1+MAX(0,A17-Assumptions!$B$8*2))*(1+MAX(0,A17-Assumptions!$B$8*3))*(1+MAX(0,A17-Assumptions!$B$8*4)) -> 25.166647 | C17: =B17*Assumptions!$B$29 -> 176.16653
A18: 0.25 | B18: =Assumptions!$B$6*(1+MAX(0,A18-Assumptions!$B$8*0))*(1+MAX(0,A18-Assumptions!$B$8*1))*(1+MAX(0,A18-Assumptions!$B$8*2))*(1+MAX(0,A18-Assumptions!$B$8*3))*(1+MAX(0,A18-Assumptions!$B$8*4)) -> 31.082401 | C18: =B18*Assumptions!$B$29 -> 217.57681
A19: 0.3 | B19: =Assumptions!$B$6*(1+MAX(0,A19-Assumptions!$B$8*0))*(1+MAX(0,A19-Assumptions!$B$8*1))*(1+MAX(0,A19-Assumptions!$B$8*2))*(1+MAX(0,A19-Assumptions!$B$8*3))*(1+MAX(0,A19-Assumptions!$B$8*4)) -> 38.061564 | C19: =B19*Assumptions!$B$29 -> 266.43095
A20: 0.35 | B20: =Assumptions!$B$6*(1+MAX(0,A20-Assumptions!$B$8*0))*(1+MAX(0,A20-Assumptions!$B$8*1))*(1+MAX(0,A20-Assumptions!$B$8*2))*(1+MAX(0,A20-Assumptions!$B$8*3))*(1+MAX(0,A20-Assumptions!$B$8*4)) -> 46.241443 | C20: =B20*Assumptions!$B$29 -> 323.6901
A21: 0.4 | B21: =Assumptions!$B$6*(1+MAX(0,A21-Assumptions!$B$8*0))*(1+MAX(0,A21-Assumptions!$B$8*1))*(1+MAX(0,A21-Assumptions!$B$8*2))*(1+MAX(0,A21-Assumptions!$B$8*3))*(1+MAX(0,A21-Assumptions!$B$8*4)) -> 55.770689 | C21: =B21*Assumptions!$B$29 -> 390.39482
A23: Retention sensitivity
A24: Net revenue retention varies while the ARR growth target is held fixed, so lower retention simply raises the New ARR the sales team must win.
A25: Net revenue retention | B25: Year 1 New ARR required | C25: Increase over base case | D25: Required new logos | E25: New ARR share of gross additions
A26: 1 | B26: =Assumptions!$B$6*(1+'Operating Forecast'!B8)-Assumptions!$B$6*A26 -> 3.6 | C26: =B26-'Operating Forecast'!B9 -> 1.2 | D26: =B26/((Assumptions!$B$6/Assumptions!$B$16)*Assumptions!$B$17) -> 62.608696 | E26: =B26/(B26+Assumptions!$B$6*(A26-Assumptions!$B$10)) -> 0.71428571
A27: 1.05 | B27: =Assumptions!$B$6*(1+'Operating Forecast'!B8)-Assumptions!$B$6*A27 -> 3 | C27: =B27-'Operating Forecast'!B9 -> 0.6 | D27: =B27/((Assumptions!$B$6/Assumptions!$B$16)*Assumptions!$B$17) -> 52.173913 | E27: =B27/(B27+Assumptions!$B$6*(A27-Assumptions!$B$10)) -> 0.5952381
A28: 1.1 | B28: =Assumptions!$B$6*(1+'Operating Forecast'!B8)-Assumptions!$B$6*A28 -> 2.4 | C28: =B28-'Operating Forecast'!B9 -> 0 | D28: =B28/((Assumptions!$B$6/Assumptions!$B$16)*Assumptions!$B$17) -> 41.73913 | E28: =B28/(B28+Assumptions!$B$6*(A28-Assumptions!$B$10)) -> 0.47619048
A29: 1.15 | B29: =Assumptions!$B$6*(1+'Operating Forecast'!B8)-Assumptions!$B$6*A29 -> 1.8 | C29: =B29-'Operating Forecast'!B9 -> -0.6 | D29: =B29/((Assumptions!$B$6/Assumptions!$B$16)*Assumptions!$B$17) -> 31.304348 | E29: =B29/(B29+Assumptions!$B$6*(A29-Assumptions!$B$10)) -> 0.35714286
A30: 1.2 | B30: =Assumptions!$B$6*(1+'Operating Forecast'!B8)-Assumptions!$B$6*A30 -> 1.2 | C30: =B30-'Operating Forecast'!B9 -> -1.2 | D30: =B30/((Assumptions!$B$6/Assumptions!$B$16)*Assumptions!$B$17) -> 20.869565 | E30: =B30/(B30+Assumptions!$B$6*(A30-Assumptions!$B$10)) -> 0.23809524
A32: Interest rate sensitivity, blended capital facility
A33: Applied to the blended facility principal. Shows where the minimum cash covenant starts to bind.
A34: Cash interest rate | B34: Year 1 cash interest | C34: Five year cash interest | D34: Year 5 closing cash | E34: Covenant status
A35: 0.09 | B35: =Assumptions!$B$46*A35 -> 1.08 | C35: =Assumptions!$B$46*A35*Assumptions!$B$51+(Assumptions!$B$46*A35+(Assumptions!$B$46-Assumptions!$B$46*Assumptions!$B$52)*A35) -> 5.346 | D35: ='Blended Capital Case'!F23+(SUM('Blended Capital Case'!B8:F8)-C35) -> 9.3196245 | E35: =IF(D35<Assumptions!$B$30,"BREACH","Headroom") -> Headroom
A36: 0.1 | B36: =Assumptions!$B$46*A36 -> 1.2 | C36: =Assumptions!$B$46*A36*Assumptions!$B$51+(Assumptions!$B$46*A36+(Assumptions!$B$46-Assumptions!$B$46*Assumptions!$B$52)*A36) -> 5.94 | D36: ='Blended Capital Case'!F23+(SUM('Blended Capital Case'!B8:F8)-C36) -> 8.7256245 | E36: =IF(D36<Assumptions!$B$30,"BREACH","Headroom") -> Headroom
A37: 0.11 | B37: =Assumptions!$B$46*A37 -> 1.32 | C37: =Assumptions!$B$46*A37*Assumptions!$B$51+(Assumptions!$B$46*A37+(Assumptions!$B$46-Assumptions!$B$46*Assumptions!$B$52)*A37) -> 6.534 | D37: ='Blended Capital Case'!F23+(SUM('Blended Capital Case'!B8:F8)-C37) -> 8.1316245 | E37: =IF(D37<Assumptions!$B$30,"BREACH","Headroom") -> Headroom
A38: 0.12 | B38: =Assumptions!$B$46*A38 -> 1.44 | C38: =Assumptions!$B$46*A38*Assumptions!$B$51+(Assumptions!$B$46*A38+(Assumptions!$B$46-Assumptions!$B$46*Assumptions!$B$52)*A38) -> 7.128 | D38: ='Blended Capital Case'!F23+(SUM('Blended Capital Case'!B8:F8)-C38) -> 7.5376245 | E38: =IF(D38<Assumptions!$B$30,"BREACH","Headroom") -> Headroom
A39: 0.13 | B39: =Assumptions!$B$46*A39 -> 1.56 | C39: =Assumptions!$B$46*A39*Assumptions!$B$51+(Assumptions!$B$46*A39+(Assumptions!$B$46-Assumptions!$B$46*Assumptions!$B$52)*A39) -> 7.722 | D39: ='Blended Capital Case'!F23+(SUM('Blended Capital Case'!B8:F8)-C39) -> 6.9436245 | E39: =IF(D39<Assumptions!$B$30,"BREACH","Headroom") -> Headroom
A41: Break even analysis
A42: At what point the cost structure stops consuming cash.
A43: Year 5 operating expenses as a percentage of revenue | B43: =-'Operating Forecast'!F21/'Operating Forecast'!F15 -> 0.75
A44: Gross margin | B44: =Assumptions!$B$11 -> 0.78
A45: Contribution margin at the year 5 cost structure | B45: =Assumptions!$B$11+'Operating Forecast'!F21/'Operating Forecast'!F15 -> 0.03
...

Sheet Downside Case
A1: Downside Case
A2: Lower growth, no net expansion, higher churn, thinner margin, and sales spend that does not fall. This is the test that separates the three structures.
A3: All figures are hypothetical and illustrative.
A5: Line item (USD millions) | B5: Year 1 | C5: Year 2 | D5: Year 3 | E5: Year 4 | F5: Year 5
A6: Beginning ARR | B6: =Assumptions!$B$6 -> 12 | C6: =B8 -> 14.16 | D6: =C8 -> 16.4256 | E6: =D8 -> 18.725184 | F6: =E8 -> 20.972206
A7: Growth rate | B7: =MAX(0,Assumptions!$B$55-Assumptions!$B$8*0) -> 0.18 | C7: =MAX(0,Assumptions!$B$55-Assumptions!$B$8*1) -> 0.16 | D7: =MAX(0,Assumptions!$B$55-Assumptions!$B$8*2) -> 0.14 | E7: =MAX(0,Assumptions!$B$55-Assumptions!$B$8*3) -> 0.12 | F7: =MAX(0,Assumptions!$B$55-Assumptions!$B$8*4) -> 0.1
A8: Ending ARR | B8: =B6*(1+B7) -> 14.16 | C8: =C6*(1+C7) -> 16.4256 | D8: =D6*(1+D7) -> 18.725184 | E8: =E6*(1+E7) -> 20.972206 | F8: =F6*(1+F7) -> 23.069427
A9: New ARR required | B9: =B8-B6*Assumptions!$B$56 -> 2.16 | C9: =C8-C6*Assumptions!$B$56 -> 2.2656 | D9: =D8-D6*Assumptions!$B$56 -> 2.299584 | E9: =E8-E6*Assumptions!$B$56 -> 2.2470221 | F9: =F8-F6*Assumptions!$B$56 -> 2.0972206
A10: Churned ARR | B10: =-B6*(1-Assumptions!$B$57) -> -2.16 | C10: =-C6*(1-Assumptions!$B$57) -> -2.5488 | D10: =-D6*(1-Assumptions!$B$57) -> -2.956608 | E10: =-E6*(1-Assumptions!$B$57) -> -3.3705331 | F10: =-F6*(1-Assumptions!$B$57) -> -3.7749971
A11: Revenue | B11: =(B6+B8)/2 -> 13.08 | C11: =(C6+C8)/2 -> 15.2928 | D11: =(D6+D8)/2 -> 17.575392 | E11: =(E6+E8)/2 -> 19.848695 | F11: =(F6+F8)/2 -> 22.020816
A12: Gross profit | B12: =B11*Assumptions!$B$58 -> 9.6792 | C12: =C11*Assumptions!$B$58 -> 11.316672 | D12: =D11*Assumptions!$B$58 -> 13.00579 | E12: =E11*Assumptions!$B$58 -> 14.688034 | F12: =F11*Assumptions!$B$58 -> 16.295404
A13: Total operating expenses | B13: =-B11*(Assumptions!B$21+Assumptions!$B$59+Assumptions!B$22+Assumptions!B$23) -> -14.1264 | C13: =-C11*(Assumptions!C$21+Assumptions!$B$59+Assumptions!C$22+Assumptions!C$23) -> -15.445728 | D13: =-D11*(Assumptions!D$21+Assumptions!$B$59+Assumptions!D$22+Assumptions!D$23) -> -16.520868 | E13: =-E11*(Assumptions!E$21+Assumptions!$B$59+Assumptions!E$22+Assumptions!E$23) -> -17.268365 | F13: =-F11*(Assumptions!F$21+Assumptions!$B$59+Assumptions!F$22+Assumptions!F$23) -> -17.616653
A14: EBITDA | B14: =B12+B13 -> -4.4472 | C14: =C12+C13 -> -4.129056 | D14: =D12+D13 -> -3.5150784 | E14: =E12+E13 -> -2.5803304 | F14: =F12+F13 -> -1.321249
A15: Capital expenditure | B15: =-B11*Assumptions!$B$12 -> -0.2616 | C15: =-C11*Assumptions!$B$12 -> -0.305856 | D15: =-D11*Assumptions!$B$12 -> -0.35150784 | E15: =-E11*Assumptions!$B$12 -> -0.3969739 | F15: =-F11*Assumptions!$B$12 -> -0.44041633
A16: Deferred revenue benefit | B16: =(B8-B6)*Assumptions!$B$13 -> 0.216 | C16: =(C8-C6)*Assumptions!$B$13 -> 0.22656 | D16: =(D8-D6)*Assumptions!$B$13 -> 0.2299584 | E16: =(E8-E6)*Assumptions!$B$13 -> 0.22470221 | F16: =(F8-F6)*Assumptions!$B$13 -> 0.20972206
A17: Unlevered free cash flow | B17: =B14+B15+B16 -> -4.4928 | C17: =C14+C15+C16 -> -4.208352 | D17: =D14+D15+D16 -> -3.6366278 | E17: =E14+E15+E16 -> -2.752602 | F17: =F14+F15+F16 -> -1.5519432
A19: Cash outcome under each structure
A20: Closing cash (USD millions) | B20: Year 1 | C20: Year 2 | D20: Year 3 | E20: Year 4 | F20: Year 5
A21: Growth equity | B21: ='Capital Structures'!B13+B17 -> 20.5072 | C21: =B21+C17 -> 16.298848 | D21: =C21+D17 -> 12.66222 | E21: =D21+E17 -> 9.9096181 | F21: =E21+F17 -> 8.3576749
A22: Private credit | B22: ='Capital Structures'!C13+B17-'Private Credit Case'!B8-'Private Credit Case'!B10 -> 17.8072 | C22: =B22+C17-'Private Credit Case'!C8-'Private Credit Case'!C10 -> 11.298848 | D22: =C22+D17-'Private Credit Case'!D8-'Private Credit Case'!D10 -> 5.3622202 | E22: =D22+E17-'Private Credit Case'!E8-'Private Credit Case'!E10 -> -0.69038189 | F22: =E22+F17-'Private Credit Case'!F8-'Private Credit Case'!F10 -> -5.4273251
