Workbook

Sheet Read Me
A1: Enterprise Software Growth Capital Model
A2: Illustrative underwriting of Northstar Workflow Systems
A4: Disclosure | B4: Northstar Workflow Systems is a hypothetical company created solely for an illustrative underwriting exercise. It is not a real business or investment opportunity.
A5: Purpose | B5: This workbook underwrites a single hypothetical B2B enterprise SaaS company across three capital structures: all growth equity, all private credit, and a blended structure combining both. The operating forecast is identical in every case, so any difference in outcome is caused by the structure rather than by the business.
A6: How to use it | B6: Every input lives on the Assumptions sheet and is shaded amber. Change any amber cell and the entire workbook recalculates, including the SaaS metrics, the debt schedules, the returns, the sensitivities, and the downside case. No output anywhere in this workbook is a hardcoded number.
A7: Colour convention | B7: Amber cells are inputs you may change. White cells are formulas driven by those inputs. Grey banded rows are subtotals. Red shading appears only where a minimum cash covenant is breached or EBITDA is negative, so the formatting carries meaning rather than decoration.
A8: Sheet order | B8: Read Me, Assumptions, Historical Financials, Operating Forecast, SaaS Metrics, Capital Structures, Growth Equity Case, Private Credit Case, Blended Capital Case, Debt Schedule, Returns Analysis, Sensitivities, Downside Case, Sources and Disclosures.
A9: Key formula: ARR bridge | B9: Ending ARR = Beginning ARR + New ARR + Expansion ARR less Churned ARR. Churned ARR is set by gross retention and Expansion ARR by the gap between net and gross retention. New ARR is then the residual required to hit the growth target, which makes the sales requirement explicit rather than assumed. If you lower net revenue retention, required New ARR rises automatically.
A10: Key formula: Revenue | B10: Revenue = average of beginning and ending ARR for the year. ARR is added through the year rather than on day one, so recognising the full ending ARR as revenue would overstate the period.
A11: Key formula: Unlevered free cash flow | B11: EBITDA less capital expenditure plus the deferred revenue benefit on ARR growth. It is stated before any interest or principal so the same cash flow line can be used across all three structures.
A12: Key formula: Debt service | B12: Cash interest on the opening balance, plus amortisation once the interest only period ends. PIK interest, if switched on, accretes to the balance rather than being paid in cash.
A13: Key formula: Exit equity value | B13: Exit enterprise value at the exit ARR multiple, plus ending cash, less ending debt. The equity investor receives their ownership percentage of that.
A14: What this workbook is not | B14: It is not a valuation of any real company, not an investment recommendation, and not a forecast. It is a demonstration of how a structure decision changes dilution, debt service risk, covenant headroom, runway, and returns when the underlying business is held constant.
A16: Built by | B16: Sahil Modi, modi.sahil@gmail.com

Sheet Assumptions
A1: Assumptions
A2: Every amber cell is an input. Everything else in the workbook derives from these.
A3: All figures are hypothetical and illustrative.
A5: Operating assumptions
A6: Beginning ARR (USD millions) | B6: 12
A7: Year 1 ARR growth rate | B7: 0.3
A8: Annual growth decay (percentage points) | B8: 0.02
A9: Net revenue retention | B9: 1.1
A10: Gross retention | B10: 0.88
A11: Gross margin | B11: 0.78
A12: Capital expenditure (% of revenue) | B12: 0.02
A13: Deferred revenue benefit (% of ARR increase) | B13: 0.1
A14: Beginning cash (USD millions) | B14: 8
A15: Existing debt (USD millions) | B15: 3
A16: Customer count at year 0 | B16: 240
A17: New customer ACV premium to base | B17: 1.15
A19: Operating expense ratios (% of revenue)
A20: Line | B20: Year 1 | C20: Year 2 | D20: Year 3 | E20: Year 4 | F20: Year 5
A21: Sales and marketing | B21: 0.55 | C21: 0.52 | D21: 0.48 | E21: 0.44 | F21: 0.4
A22: Research and development | B22: 0.3 | C22: 0.28 | D22: 0.26 | E22: 0.24 | F22: 0.22
A23: General and administrative | B23: 0.18 | C23: 0.16 | D23: 0.15 | E23: 0.14 | F23: 0.13
A25: Transaction assumptions
A26: Total capital raised (USD millions) | B26: 20
A27: Existing debt refinanced at close (USD millions) | B27: 3
A28: Entry ARR multiple (pre-money) | B28: 8
A29: Exit ARR multiple | B29: 7
A30: Minimum cash covenant (USD millions) | B30: 5
A32: Growth equity case
A33: New equity invested (USD millions) | B33: 20
A35: Private credit case
A36: Principal (USD millions) | B36: 20
A37: Cash interest rate | B37: 0.115
A38: PIK interest rate | B38: 0
A39: Original issue discount | B39: 0.02
A40: Maturity (years) | B40: 5
A41: Interest only period (years) | B41: 3
A42: Annual amortisation (% of original principal) | B42: 0.05
A44: Blended capital case
A45: Equity component (USD millions) | B45: 8
A46: Debt component (USD millions) | B46: 12
...

Sheet Historical Financials
A1: Historical Financials
A2: Illustrative three year history for Northstar Workflow Systems, ending at the model start point.
A3: All figures are hypothetical and illustrative.
A5: Line item (USD millions) | B5: Year -3 | C5: Year -2 | D5: Year -1 | E5: Year 0
A6: Ending ARR | B6: 4.9 | C6: 6.9 | D6: 9.4 | E6: =Assumptions!$B$6
A7: ARR growth | B7: n/a | C7: =C6/B6-1 | D7: =D6/C6-1 | E7: =E6/D6-1
A8: Revenue | B8: =B6*0.85 | C8: =(B6+C6)/2 | D8: =(C6+D6)/2 | E8: =(D6+E6)/2
A9: Gross profit | B9: =B8*Assumptions!$B$11 | C9: =C8*Assumptions!$B$11 | D9: =D8*Assumptions!$B$11 | E9: =E8*Assumptions!$B$11
A10: Total operating expenses | B10: 5.4 | C10: 7.3 | D10: 9.6 | E10: 12.7
A11: EBITDA | B11: =B9-B10 | C11: =C9-C10 | D11: =D9-D10 | E11: =E9-E10
A12: Cash balance | B12: 6.2 | C12: 9.8 | D12: 7.1 | E12: =Assumptions!$B$14
A13: Customer count | B13: 118 | C13: 156 | D13: 199 | E13: =Assumptions!$B$16
A15: History is illustrative and is provided so the forecast has a visible starting trajectory. Year 0 ARR, cash, and customer count link to the Assumptions sheet, so the history and the forecast always join.
A17: All figures are hypothetical and illustrative.

Sheet Operating Forecast
A1: Operating Forecast
A2: Five year base case. Churn and expansion are set by retention; New ARR is the residual required to hit the growth target.
A3: All figures are hypothetical and illustrative.
A5: Line item (USD millions) | B5: Year 1 | C5: Year 2 | D5: Year 3 | E5: Year 4 | F5: Year 5
A6: ARR bridge
A7: Beginning ARR | B7: =Assumptions!$B$6 | C7: =B12 | D7: =C12 | E7: =D12 | F7: =E12
A8: Growth rate | B8: =MAX(0,Assumptions!$B$7-Assumptions!$B$8*0) | C8: =MAX(0,Assumptions!$B$7-Assumptions!$B$8*1) | D8: =MAX(0,Assumptions!$B$7-Assumptions!$B$8*2) | E8: =MAX(0,Assumptions!$B$7-Assumptions!$B$8*3) | F8: =MAX(0,Assumptions!$B$7-Assumptions!$B$8*4)
A9: New ARR | B9: =B7*(1+B8)-B7*Assumptions!$B$9 | C9: =C7*(1+C8)-C7*Assumptions!$B$9 | D9: =D7*(1+D8)-D7*Assumptions!$B$9 | E9: =E7*(1+E8)-E7*Assumptions!$B$9 | F9: =F7*(1+F8)-F7*Assumptions!$B$9
A10: Expansion ARR | B10: =B7*(Assumptions!$B$9-Assumptions!$B$10) | C10: =C7*(Assumptions!$B$9-Assumptions!$B$10) | D10: =D7*(Assumptions!$B$9-Assumptions!$B$10) | E10: =E7*(Assumptions!$B$9-Assumptions!$B$10) | F10: =F7*(Assumptions!$B$9-Assumptions!$B$10)
A11: Churned ARR | B11: =-B7*(1-Assumptions!$B$10) | C11: =-C7*(1-Assumptions!$B$10) | D11: =-D7*(1-Assumptions!$B$10) | E11: =-E7*(1-Assumptions!$B$10) | F11: =-F7*(1-Assumptions!$B$10)
A12: Ending ARR | B12: =B7+B9+B10+B11 | C12: =C7+C9+C10+C11 | D12: =D7+D9+D10+D11 | E12: =E7+E9+E10+E11 | F12: =F7+F9+F10+F11
A14: Income statement
A15: Revenue | B15: =(B7+B12)/2 | C15: =(C7+C12)/2 | D15: =(D7+D12)/2 | E15: =(E7+E12)/2 | F15: =(F7+F12)/2
A16: Gross profit | B16: =B15*Assumptions!$B$11 | C16: =C15*Assumptions!$B$11 | D16: =D15*Assumptions!$B$11 | E16: =E15*Assumptions!$B$11 | F16: =F15*Assumptions!$B$11
A17: Gross margin | B17: =B16/B15 | C17: =C16/C15 | D17: =D16/D15 | E17: =E16/E15 | F17: =F16/F15
A18: Sales and marketing | B18: =-B15*Assumptions!B$21 | C18: =-C15*Assumptions!C$21 | D18: =-D15*Assumptions!D$21 | E18: =-E15*Assumptions!E$21 | F18: =-F15*Assumptions!F$21
A19: Research and development | B19: =-B15*Assumptions!B$22 | C19: =-C15*Assumptions!C$22 | D19: =-D15*Assumptions!D$22 | E19: =-E15*Assumptions!E$22 | F19: =-F15*Assumptions!F$22
A20: General and administrative | B20: =-B15*Assumptions!B$23 | C20: =-C15*Assumptions!C$23 | D20: =-D15*Assumptions!D$23 | E20: =-E15*Assumptions!E$23 | F20: =-F15*Assumptions!F$23
A21: Total operating expenses | B21: =SUM(B18:B20) | C21: =SUM(C18:C20) | D21: =SUM(D18:D20) | E21: =SUM(E18:E20) | F21: =SUM(F18:F20)
A22: EBITDA | B22: =B16+B21 | C22: =C16+C21 | D22: =D16+D21 | E22: =E16+E21 | F22: =F16+F21
A23: EBITDA margin | B23: =B22/B15 | C23: =C22/C15 | D23: =D22/D15 | E23: =E22/E15 | F23: =F22/F15
A25: Cash flow
A26: Capital expenditure | B26: =-B15*Assumptions!$B$12 | C26: =-C15*Assumptions!$B$12 | D26: =-D15*Assumptions!$B$12 | E26: =-E15*Assumptions!$B$12 | F26: =-F15*Assumptions!$B$12
A27: Deferred revenue benefit | B27: =(B12-B7)*Assumptions!$B$13 | C27: =(C12-C7)*Assumptions!$B$13 | D27: =(D12-D7)*Assumptions!$B$13 | E27: =(E12-E7)*Assumptions!$B$13 | F27: =(F12-F7)*Assumptions!$B$13
A28: Unlevered free cash flow | B28: =B22+B26+B27 | C28: =C22+C26+C27 | D28: =D22+D26+D27 | E28: =E22+E26+E27 | F28: =F22+F26+F27
A30: Customers
A31: Beginning customers | B31: =Assumptions!$B$16 | C31: =B34 | D31: =C34 | E31: =D34 | F31: =E34
A32: New customers | B32: =B9/((B7/B31)*Assumptions!$B$17) | C32: =C9/((C7/C31)*Assumptions!$B$17) | D32: =D9/((D7/D31)*Assumptions!$B$17) | E32: =E9/((E7/E31)*Assumptions!$B$17) | F32: =F9/((F7/F31)*Assumptions!$B$17)
A33: Churned customers | B33: =-B31*(1-Assumptions!$B$10) | C33: =-C31*(1-Assumptions!$B$10) | D33: =-D31*(1-Assumptions!$B$10) | E33: =-E31*(1-Assumptions!$B$10) | F33: =-F31*(1-Assumptions!$B$10)
A34: Ending customers | B34: =B31+B32+B33 | C34: =C31+C32+C33 | D34: =D31+D32+D33 | E34: =E31+E32+E33 | F34: =F31+F32+F33
A36: All figures are hypothetical and illustrative.

Sheet SaaS Metrics
A1: SaaS Metrics
A2: The metrics a growth capital or private credit investor tests first. All derived from the Operating Forecast.
A3: All figures are hypothetical and illustrative.
A5: Metric | B5: Year 1 | C5: Year 2 | D5: Year 3 | E5: Year 4 | F5: Year 5
A6: ARR growth | B6: ='Operating Forecast'!B8 | C6: ='Operating Forecast'!C8 | D6: ='Operating Forecast'!D8 | E6: ='Operating Forecast'!E8 | F6: ='Operating Forecast'!F8
A7: Net revenue retention | B7: =Assumptions!$B$9 | C7: =Assumptions!$B$9 | D7: =Assumptions!$B$9 | E7: =Assumptions!$B$9 | F7: =Assumptions!$B$9
A8: Gross retention | B8: =Assumptions!$B$10 | C8: =Assumptions!$B$10 | D8: =Assumptions!$B$10 | E8: =Assumptions!$B$10 | F8: =Assumptions!$B$10
A9: Gross margin | B9: ='Operating Forecast'!B17 | C9: ='Operating Forecast'!C17 | D9: ='Operating Forecast'!D17 | E9: ='Operating Forecast'!E17 | F9: ='Operating Forecast'!F17
A10: CAC payback (months) | B10: =-'Operating Forecast'!B18/(('Operating Forecast'!B9+'Operating Forecast'!B10)*Assumptions!$B$11)*12 | C10: =-'Operating Forecast'!C18/(('Operating Forecast'!C9+'Operating Forecast'!C10)*Assumptions!$B$11)*12 | D10: =-'Operating Forecast'!D18/(('Operating Forecast'!D9+'Operating Forecast'!D10)*Assumptions!$B$11)*12 | E10: =-'Operating Forecast'!E18/(('Operating Forecast'!E9+'Operating Forecast'!E10)*Assumptions!$B$11)*12 | F10: =-'Operating Forecast'!F18/(('Operating Forecast'!F9+'Operating Forecast'!F10)*Assumptions!$B$11)*12
A11: Burn multiple | B11: =IF('Operating Forecast'!B28>=0,"n/a",-'Operating Forecast'!B28/('Operating Forecast'!B12-'Operating Forecast'!B7)) | C11: =IF('Operating Forecast'!C28>=0,"n/a",-'Operating Forecast'!C28/('Operating Forecast'!C12-'Operating Forecast'!C7)) | D11: =IF('Operating Forecast'!D28>=0,"n/a",-'Operating Forecast'!D28/('Operating Forecast'!D12-'Operating Forecast'!D7)) | E11: =IF('Operating Forecast'!E28>=0,"n/a",-'Operating Forecast'!E28/('Operating Forecast'!E12-'Operating Forecast'!E7)) | F11: =IF('Operating Forecast'!F28>=0,"n/a",-'Operating Forecast'!F28/('Operating Forecast'!F12-'Operating Forecast'!F7))
A12: Rule of 40 | B12: ='Operating Forecast'!B8*100+'Operating Forecast'!B23*100 | C12: ='Operating Forecast'!C8*100+'Operating Forecast'!C23*100 | D12: ='Operating Forecast'!D8*100+'Operating Forecast'!D23*100 | E12: ='Operating Forecast'!E8*100+'Operating Forecast'!E23*100 | F12: ='Operating Forecast'!F8*100+'Operating Forecast'!F23*100
A13: Customer count | B13: ='Operating Forecast'!B34 | C13: ='Operating Forecast'!C34 | D13: ='Operating Forecast'!D34 | E13: ='Operating Forecast'!E34 | F13: ='Operating Forecast'!F34
A14: Average contract value (USD thousands) | B14: ='Operating Forecast'!B12/'Operating Forecast'!B34*1000 | C14: ='Operating Forecast'!C12/'Operating Forecast'!C34*1000 | D14: ='Operating Forecast'!D12/'Operating Forecast'!D34*1000 | E14: ='Operating Forecast'!E12/'Operating Forecast'!E34*1000 | F14: ='Operating Forecast'!F12/'Operating Forecast'!F34*1000
A15: Revenue per customer (USD thousands) | B15: ='Operating Forecast'!B15/'Operating Forecast'!B34*1000 | C15: ='Operating Forecast'!C15/'Operating Forecast'!C34*1000 | D15: ='Operating Forecast'!D15/'Operating Forecast'!D34*1000 | E15: ='Operating Forecast'!E15/'Operating Forecast'!E34*1000 | F15: ='Operating Forecast'!F15/'Operating Forecast'!F34*1000
A17: Where this case is strong: net revenue retention above 100 percent means the installed base grows without new logos, and the burn multiple improves every year. Where it is weak: Rule of 40 never reaches 40 inside the forecast, and gross retention of 88 percent means 12 percent of the base is lost annually. Gross retention is the single assumption most worth challenging in diligence.
A19: All figures are hypothetical and illustrative.

Sheet Capital Structures
A1: Capital Structures
A2: The same capital requirement under three structures. The operating forecast is identical in every case.
A3: All figures are hypothetical and illustrative.
A5: Term | B5: Growth equity | C5: Private credit | D5: Blended capital
A6: Total capital raised | B6: =Assumptions!$B$26 | C6: =Assumptions!$B$26 | D6: =Assumptions!$B$26
A7: Equity component | B7: =Assumptions!$B$33 | C7: =0 | D7: =Assumptions!$B$45
A8: Debt component | B8: =0 | C8: =Assumptions!$B$36 | D8: =Assumptions!$B$46
A9: Original issue discount rate | B9: =0 | C9: =Assumptions!$B$39 | D9: =Assumptions!$B$49
A10: Original issue discount cost | B10: =0 | C10: =C8*C9 | D10: =D8*D9
A11: Net proceeds at close | B11: =B7+B8-B10 | C11: =C7+C8-C10 | D11: =D7+D8-D10
A12: Less existing debt refinanced | B12: =-Assumptions!$B$27 | C12: =-Assumptions!$B$27 | D12: =-Assumptions!$B$27
A13: Cash at close | B13: =Assumptions!$B$14+B11+B12 | C13: =Assumptions!$B$14+C11+C12 | D13: =Assumptions!$B$14+D11+D12
A15: Ownership
A16: Pre-money valuation | B16: =Assumptions!$B$6*Assumptions!$B$28 | C16: =Assumptions!$B$6*Assumptions!$B$28 | D16: =Assumptions!$B$6*Assumptions!$B$28
A17: Post-money valuation | B17: =B16+B7 | C17: =C16 | D17: =D16+D7
A18: Investor ownership | B18: =B7/B17 | C18: =0 | D18: =D7/D17
A19: Founder and existing holder dilution | B19: =B18 | C19: =C18 | D19: =D18
A21: Debt terms
A22: Cash interest rate | B22: =0 | C22: =Assumptions!$B$37 | D22: =Assumptions!$B$47
A23: PIK interest rate | B23: =0 | C23: =Assumptions!$B$38 | D23: =Assumptions!$B$48
A24: Maturity (years) | B24: =0 | C24: =Assumptions!$B$40 | D24: =Assumptions!$B$50
A25: Interest only period (years) | B25: =0 | C25: =Assumptions!$B$41 | D25: =Assumptions!$B$51
A26: Annual amortisation (% of principal) | B26: =0 | C26: =Assumptions!$B$42 | D26: =Assumptions!$B$52
A28: Uses of proceeds are identical across all three structures: the existing term debt is refinanced in full at close and the balance funds product development, enterprise sales hiring, international expansion, working capital, and selective acquisitions. Holding uses constant is what makes the three structures comparable.
A30: All figures are hypothetical and illustrative.

Sheet Growth Equity Case
A1: Growth Equity Case
A2: USD 20 million of primary equity. No leverage. The safest structure and the most expensive in ownership terms.
A3: All figures are hypothetical and illustrative.
A5: Cash roll forward
A6: Line item (USD millions) | B6: Year 1 | C6: Year 2 | D6: Year 3 | E6: Year 4 | F6: Year 5
A7: Opening cash | B7: ='Capital Structures'!B13 | C7: =B11 | D7: =C11 | E7: =D11 | F7: =E11
A8: Unlevered free cash flow | B8: ='Operating Forecast'!B28 | C8: ='Operating Forecast'!C28 | D8: ='Operating Forecast'!D28 | E8: ='Operating Forecast'!E28 | F8: ='Operating Forecast'!F28
A9: Cash interest | B9: =0 | C9: =0 | D9: =0 | E9: =0 | F9: =0
A10: Amortisation | B10: =0 | C10: =0 | D10: =0 | E10: =0 | F10: =0
A11: Closing cash | B11: =SUM(B7:B10) | C11: =SUM(C7:C10) | D11: =SUM(D7:D10) | E11: =SUM(E7:E10) | F11: =SUM(F7:F10)
A12: Minimum cash covenant | B12: =Assumptions!$B$30 | C12: =Assumptions!$B$30 | D12: =Assumptions!$B$30 | E12: =Assumptions!$B$30 | F12: =Assumptions!$B$30
A13: Covenant headroom | B13: =B11-B12 | C13: =C11-C12 | D13: =D11-D12 | E13: =E11-E12 | F13: =F11-F12
A14: Covenant status | B14: =IF(B11<B12,"BREACH","Headroom") | C14: =IF(C11<C12,"BREACH","Headroom") | D14: =IF(D11<D12,"BREACH","Headroom") | E14: =IF(E11<E12,"BREACH","Headroom") | F14: =IF(F11<F12,"BREACH","Headroom")
A15: Runway (months at current burn) | B15: =IF(B11-B7>=0,"cash generative",B11/(B7-B11)*12) | C15: =IF(C11-C7>=0,"cash generative",C11/(C7-C11)*12) | D15: =IF(D11-D7>=0,"cash generative",D11/(D7-D11)*12) | E15: =IF(E11-E7>=0,"cash generative",E11/(E7-E11)*12) | F15: =IF(F11-F7>=0,"cash generative",F11/(F7-F11)*12)
A17: Exit and returns
A18: Year 5 ending ARR | B18: ='Operating Forecast'!F12
A19: Exit ARR multiple | B19: =Assumptions!$B$29
A20: Exit enterprise value | B20: =B18*B19
A21: Plus year 5 cash | B21: =F11
A22: Less year 5 debt | B22: =0
A23: Exit equity value | B23: =B20+B21+B22
A24: Equity investor ownership | B24: ='Capital Structures'!B18
A25: Equity invested | B25: =Assumptions!$B$33
A26: Equity investor proceeds at exit | B26: =B23*B24
A27: Equity investor MOIC | B27: =IF(B25=0,"n/a",B26/B25)
A28: Equity investor IRR | B28: =IF(B25=0,"n/a",(B26/B25)^(1/5)-1)
A30: All figures are hypothetical and illustrative.

Sheet Private Credit Case
A1: Private Credit Case
A2: USD 20 million senior secured. No dilution, and the company cannot service it from operating cash flow.
A3: All figures are hypothetical and illustrative.
A5: Debt schedule
A6: Line item (USD millions) | B6: Year 1 | C6: Year 2 | D6: Year 3 | E6: Year 4 | F6: Year 5
A7: Opening balance | B7: =Assumptions!$B$36 | C7: =B12 | D7: =C12 | E7: =D12 | F7: =E12
A8: Cash interest | B8: =B7*Assumptions!$B$37 | C8: =C7*Assumptions!$B$37 | D8: =D7*Assumptions!$B$37 | E8: =E7*Assumptions!$B$37 | F8: =F7*Assumptions!$B$37
A9: PIK interest | B9: =B7*Assumptions!$B$38 | C9: =C7*Assumptions!$B$38 | D9: =D7*Assumptions!$B$38 | E9: =E7*Assumptions!$B$38 | F9: =F7*Assumptions!$B$38
A10: Amortisation | B10: =IF(1>Assumptions!$B$41,Assumptions!$B$36*Assumptions!$B$42,0) | C10: =IF(2>Assumptions!$B$41,Assumptions!$B$36*Assumptions!$B$42,0) | D10: =IF(3>Assumptions!$B$41,Assumptions!$B$36*Assumptions!$B$42,0) | E10: =IF(4>Assumptions!$B$41,Assumptions!$B$36*Assumptions!$B$42,0) | F10: =IF(5>Assumptions!$B$41,Assumptions!$B$36*Assumptions!$B$42,0)
A11: Debt service | B11: =B8+B10 | C11: =C8+C10 | D11: =D8+D10 | E11: =E8+E10 | F11: =F8+F10
A12: Closing balance | B12: =B7+B9-B10 | C12: =C7+C9-C10 | D12: =D7+D9-D10 | E12: =E7+E9-E10 | F12: =F7+F9-F10
A13: Debt to ending ARR | B13: =B12/'Operating Forecast'!B12 | C13: =C12/'Operating Forecast'!C12 | D13: =D12/'Operating Forecast'!D12 | E13: =E12/'Operating Forecast'!E12 | F13: =F12/'Operating Forecast'!F12
A14: Interest coverage (EBITDA / cash interest) | B14: =IF(B8=0,"n/a",'Operating Forecast'!B22/B8) | C14: =IF(C8=0,"n/a",'Operating Forecast'!C22/C8) | D14: =IF(D8=0,"n/a",'Operating Forecast'!D22/D8) | E14: =IF(E8=0,"n/a",'Operating Forecast'!E22/E8) | F14: =IF(F8=0,"n/a",'Operating Forecast'!F22/F8)
A15: Debt service coverage ratio | B15: =IF(B11=0,"n/a",('Operating Forecast'!B22+'Operating Forecast'!B26)/B11) | C15: =IF(C11=0,"n/a",('Operating Forecast'!C22+'Operating Forecast'!C26)/C11) | D15: =IF(D11=0,"n/a",('Operating Forecast'!D22+'Operating Forecast'!D26)/D11) | E15: =IF(E11=0,"n/a",('Operating Forecast'!E22+'Operating Forecast'!E26)/E11) | F15: =IF(F11=0,"n/a",('Operating Forecast'!F22+'Operating Forecast'!F26)/F11)
A17: Cash roll forward
A18: Line item (USD millions) | B18: Year 1 | C18: Year 2 | D18: Year 3 | E18: Year 4 | F18: Year 5
A19: Opening cash | B19: ='Capital Structures'!C13 | C19: =B23 | D19: =C23 | E19: =D23 | F19: =E23
A20: Unlevered free cash flow | B20: ='Operating Forecast'!B28 | C20: ='Operating Forecast'!C28 | D20: ='Operating Forecast'!D28 | E20: ='Operating Forecast'!E28 | F20: ='Operating Forecast'!F28
A21: Cash interest | B21: =-B8 | C21: =-C8 | D21: =-D8 | E21: =-E8 | F21: =-F8
A22: Amortisation | B22: =-B10 | C22: =-C10 | D22: =-D10 | E22: =-E10 | F22: =-F10
A23: Closing cash | B23: =SUM(B19:B22) | C23: =SUM(C19:C22) | D23: =SUM(D19:D22) | E23: =SUM(E19:E22) | F23: =SUM(F19:F22)
A24: Minimum cash covenant | B24: =Assumptions!$B$30 | C24: =Assumptions!$B$30 | D24: =Assumptions!$B$30 | E24: =Assumptions!$B$30 | F24: =Assumptions!$B$30
A25: Covenant headroom | B25: =B23-B24 | C25: =C23-C24 | D25: =D23-D24 | E25: =E23-E24 | F25: =F23-F24
A26: Covenant status | B26: =IF(B23<B24,"BREACH","Headroom") | C26: =IF(C23<C24,"BREACH","Headroom") | D26: =IF(D23<D24,"BREACH","Headroom") | E26: =IF(E23<E24,"BREACH","Headroom") | F26: =IF(F23<F24,"BREACH","Headroom")
A27: Runway (months at current burn) | B27: =IF(B23-B19>=0,"cash generative",B23/(B19-B23)*12) | C27: =IF(C23-C19>=0,"cash generative",C23/(C19-C23)*12) | D27: =IF(D23-D19>=0,"cash generative",D23/(D19-D23)*12) | E27: =IF(E23-E19>=0,"cash generative",E23/(E19-E23)*12) | F27: =IF(F23-F19>=0,"cash generative",F23/(F19-F23)*12)
A29: Exit and returns
A30: Year 5 ending ARR | B30: ='Operating Forecast'!F12
A31: Exit ARR multiple | B31: =Assumptions!$B$29
A32: Exit enterprise value | B32: =B30*B31
A33: Plus year 5 cash | B33: =F23
A34: Less year 5 debt | B34: =-F12
A35: Exit equity value | B35: =B32+B33+B34
A36: Equity investor ownership | B36: ='Capital Structures'!C18
A37: Equity invested | B37: =0
A38: Equity investor proceeds at exit | B38: =B35*B36
A39: Equity investor MOIC | B39: =IF(B37=0,"n/a",B38/B37)
A40: Equity investor IRR | B40: =IF(B37=0,"n/a",(B38/B37)^(1/5)-1)
A42: Debt investor return
A43: Principal advanced | B43: =Assumptions!$B$36
A44: Less original issue discount | B44: =-Assumptions!$B$36*Assumptions!$B$39
...

Sheet Blended Capital Case
A1: Blended Capital Case
A2: USD 8 million of primary equity alongside a USD 12 million senior secured facility. The recommended structure.
A3: All figures are hypothetical and illustrative.
A5: Debt schedule
A6: Line item (USD millions) | B6: Year 1 | C6: Year 2 | D6: Year 3 | E6: Year 4 | F6: Year 5
A7: Opening balance | B7: =Assumptions!$B$46 | C7: =B12 | D7: =C12 | E7: =D12 | F7: =E12
A8: Cash interest | B8: =B7*Assumptions!$B$47 | C8: =C7*Assumptions!$B$47 | D8: =D7*Assumptions!$B$47 | E8: =E7*Assumptions!$B$47 | F8: =F7*Assumptions!$B$47
A9: PIK interest | B9: =B7*Assumptions!$B$48 | C9: =C7*Assumptions!$B$48 | D9: =D7*Assumptions!$B$48 | E9: =E7*Assumptions!$B$48 | F9: =F7*Assumptions!$B$48
A10: Amortisation | B10: =IF(1>Assumptions!$B$51,Assumptions!$B$46*Assumptions!$B$52,0) | C10: =IF(2>Assumptions!$B$51,Assumptions!$B$46*Assumptions!$B$52,0) | D10: =IF(3>Assumptions!$B$51,Assumptions!$B$46*Assumptions!$B$52,0) | E10: =IF(4>Assumptions!$B$51,Assumptions!$B$46*Assumptions!$B$52,0) | F10: =IF(5>Assumptions!$B$51,Assumptions!$B$46*Assumptions!$B$52,0)
A11: Debt service | B11: =B8+B10 | C11: =C8+C10 | D11: =D8+D10 | E11: =E8+E10 | F11: =F8+F10
A12: Closing balance | B12: =B7+B9-B10 | C12: =C7+C9-C10 | D12: =D7+D9-D10 | E12: =E7+E9-E10 | F12: =F7+F9-F10
A13: Debt to ending ARR | B13: =B12/'Operating Forecast'!B12 | C13: =C12/'Operating Forecast'!C12 | D13: =D12/'Operating Forecast'!D12 | E13: =E12/'Operating Forecast'!E12 | F13: =F12/'Operating Forecast'!F12
A14: Interest coverage (EBITDA / cash interest) | B14: =IF(B8=0,"n/a",'Operating Forecast'!B22/B8) | C14: =IF(C8=0,"n/a",'Operating Forecast'!C22/C8) | D14: =IF(D8=0,"n/a",'Operating Forecast'!D22/D8) | E14: =IF(E8=0,"n/a",'Operating Forecast'!E22/E8) | F14: =IF(F8=0,"n/a",'Operating Forecast'!F22/F8)
A15: Debt service coverage ratio | B15: =IF(B11=0,"n/a",('Operating Forecast'!B22+'Operating Forecast'!B26)/B11) | C15: =IF(C11=0,"n/a",('Operating Forecast'!C22+'Operating Forecast'!C26)/C11) | D15: =IF(D11=0,"n/a",('Operating Forecast'!D22+'Operating Forecast'!D26)/D11) | E15: =IF(E11=0,"n/a",('Operating Forecast'!E22+'Operating Forecast'!E26)/E11) | F15: =IF(F11=0,"n/a",('Operating Forecast'!F22+'Operating Forecast'!F26)/F11)
A17: Cash roll forward
A18: Line item (USD millions) | B18: Year 1 | C18: Year 2 | D18: Year 3 | E18: Year 4 | F18: Year 5
A19: Opening cash | B19: ='Capital Structures'!D13 | C19: =B23 | D19: =C23 | E19: =D23 | F19: =E23
A20: Unlevered free cash flow | B20: ='Operating Forecast'!B28 | C20: ='Operating Forecast'!C28 | D20: ='Operating Forecast'!D28 | E20: ='Operating Forecast'!E28 | F20: ='Operating Forecast'!F28
A21: Cash interest | B21: =-B8 | C21: =-C8 | D21: =-D8 | E21: =-E8 | F21: =-F8
A22: Amortisation | B22: =-B10 | C22: =-C10 | D22: =-D10 | E22: =-E10 | F22: =-F10
A23: Closing cash | B23: =SUM(B19:B22) | C23: =SUM(C19:C22) | D23: =SUM(D19:D22) | E23: =SUM(E19:E22) | F23: =SUM(F19:F22)
A24: Minimum cash covenant | B24: =Assumptions!$B$30 | C24: =Assumptions!$B$30 | D24: =Assumptions!$B$30 | E24: =Assumptions!$B$30 | F24: =Assumptions!$B$30
A25: Covenant headroom | B25: =B23-B24 | C25: =C23-C24 | D25: =D23-D24 | E25: =E23-E24 | F25: =F23-F24
A26: Covenant status | B26: =IF(B23<B24,"BREACH","Headroom") | C26: =IF(C23<C24,"BREACH","Headroom") | D26: =IF(D23<D24,"BREACH","Headroom") | E26: =IF(E23<E24,"BREACH","Headroom") | F26: =IF(F23<F24,"BREACH","Headroom")
A27: Runway (months at current burn) | B27: =IF(B23-B19>=0,"cash generative",B23/(B19-B23)*12) | C27: =IF(C23-C19>=0,"cash generative",C23/(C19-C23)*12) | D27: =IF(D23-D19>=0,"cash generative",D23/(D19-D23)*12) | E27: =IF(E23-E19>=0,"cash generative",E23/(E19-E23)*12) | F27: =IF(F23-F19>=0,"cash generative",F23/(F19-F23)*12)
A29: Exit and returns
A30: Year 5 ending ARR | B30: ='Operating Forecast'!F12
A31: Exit ARR multiple | B31: =Assumptions!$B$29
A32: Exit enterprise value | B32: =B30*B31
A33: Plus year 5 cash | B33: =F23
A34: Less year 5 debt | B34: =-F12
A35: Exit equity value | B35: =B32+B33+B34
A36: Equity investor ownership | B36: ='Capital Structures'!D18
A37: Equity invested | B37: =Assumptions!$B$45
A38: Equity investor proceeds at exit | B38: =B35*B36
A39: Equity investor MOIC | B39: =IF(B37=0,"n/a",B38/B37)
A40: Equity investor IRR | B40: =IF(B37=0,"n/a",(B38/B37)^(1/5)-1)
A42: Debt investor return
A43: Principal advanced | B43: =Assumptions!$B$46
A44: Less original issue discount | B44: =-Assumptions!$B$46*Assumptions!$B$49
...

Sheet Debt Schedule
A1: Debt Schedule
A2: Both debt structures side by side, drawn from the case sheets. Terms are editable on the Assumptions sheet.
A3: All figures are hypothetical and illustrative.
A5: Private credit: USD 20 million facility
A6: Line item (USD millions) | B6: Year 1 | C6: Year 2 | D6: Year 3 | E6: Year 4 | F6: Year 5
A7: Opening balance | B7: ='Private Credit Case'!B7 | C7: ='Private Credit Case'!C7 | D7: ='Private Credit Case'!D7 | E7: ='Private Credit Case'!E7 | F7: ='Private Credit Case'!F7
A8: Cash interest | B8: ='Private Credit Case'!B8 | C8: ='Private Credit Case'!C8 | D8: ='Private Credit Case'!D8 | E8: ='Private Credit Case'!E8 | F8: ='Private Credit Case'!F8
A9: PIK interest | B9: ='Private Credit Case'!B9 | C9: ='Private Credit Case'!C9 | D9: ='Private Credit Case'!D9 | E9: ='Private Credit Case'!E9 | F9: ='Private Credit Case'!F9
A10: Amortisation | B10: ='Private Credit Case'!B10 | C10: ='Private Credit Case'!C10 | D10: ='Private Credit Case'!D10 | E10: ='Private Credit Case'!E10 | F10: ='Private Credit Case'!F10
A11: Debt service | B11: ='Private Credit Case'!B11 | C11: ='Private Credit Case'!C11 | D11: ='Private Credit Case'!D11 | E11: ='Private Credit Case'!E11 | F11: ='Private Credit Case'!F11
A12: Closing balance | B12: ='Private Credit Case'!B12 | C12: ='Private Credit Case'!C12 | D12: ='Private Credit Case'!D12 | E12: ='Private Credit Case'!E12 | F12: ='Private Credit Case'!F12
A13: Debt to ending ARR | B13: ='Private Credit Case'!B13 | C13: ='Private Credit Case'!C13 | D13: ='Private Credit Case'!D13 | E13: ='Private Credit Case'!E13 | F13: ='Private Credit Case'!F13
A14: Interest coverage | B14: ='Private Credit Case'!B14 | C14: ='Private Credit Case'!C14 | D14: ='Private Credit Case'!D14 | E14: ='Private Credit Case'!E14 | F14: ='Private Credit Case'!F14
A15: Debt service coverage ratio | B15: ='Private Credit Case'!B15 | C15: ='Private Credit Case'!C15 | D15: ='Private Credit Case'!D15 | E15: ='Private Credit Case'!E15 | F15: ='Private Credit Case'!F15
A17: Blended capital: USD 12 million facility
A18: Line item (USD millions) | B18: Year 1 | C18: Year 2 | D18: Year 3 | E18: Year 4 | F18: Year 5
A19: Opening balance | B19: ='Blended Capital Case'!B7 | C19: ='Blended Capital Case'!C7 | D19: ='Blended Capital Case'!D7 | E19: ='Blended Capital Case'!E7 | F19: ='Blended Capital Case'!F7
A20: Cash interest | B20: ='Blended Capital Case'!B8 | C20: ='Blended Capital Case'!C8 | D20: ='Blended Capital Case'!D8 | E20: ='Blended Capital Case'!E8 | F20: ='Blended Capital Case'!F8
A21: PIK interest | B21: ='Blended Capital Case'!B9 | C21: ='Blended Capital Case'!C9 | D21: ='Blended Capital Case'!D9 | E21: ='Blended Capital Case'!E9 | F21: ='Blended Capital Case'!F9
A22: Amortisation | B22: ='Blended Capital Case'!B10 | C22: ='Blended Capital Case'!C10 | D22: ='Blended Capital Case'!D10 | E22: ='Blended Capital Case'!E10 | F22: ='Blended Capital Case'!F10
A23: Debt service | B23: ='Blended Capital Case'!B11 | C23: ='Blended Capital Case'!C11 | D23: ='Blended Capital Case'!D11 | E23: ='Blended Capital Case'!E11 | F23: ='Blended Capital Case'!F11
A24: Closing balance | B24: ='Blended Capital Case'!B12 | C24: ='Blended Capital Case'!C12 | D24: ='Blended Capital Case'!D12 | E24: ='Blended Capital Case'!E12 | F24: ='Blended Capital Case'!F12
A25: Debt to ending ARR | B25: ='Blended Capital Case'!B13 | C25: ='Blended Capital Case'!C13 | D25: ='Blended Capital Case'!D13 | E25: ='Blended Capital Case'!E13 | F25: ='Blended Capital Case'!F13
A26: Interest coverage | B26: ='Blended Capital Case'!B14 | C26: ='Blended Capital Case'!C14 | D26: ='Blended Capital Case'!D14 | E26: ='Blended Capital Case'!E14 | F26: ='Blended Capital Case'!F14
A27: Debt service coverage ratio | B27: ='Blended Capital Case'!B15 | C27: ='Blended Capital Case'!C15 | D27: ='Blended Capital Case'!D15 | E27: ='Blended Capital Case'!E15 | F27: ='Blended Capital Case'!F15
A29: Interest coverage is EBITDA divided by cash interest and is negative for as long as EBITDA is negative. Debt service coverage is EBITDA less capital expenditure over total debt service. Neither ratio reaches 1.0x on the USD 20 million facility inside the forecast period, which is the arithmetic reason the all debt structure is rejected.
A31: All figures are hypothetical and illustrative.

Sheet Returns Analysis
A1: Returns Analysis
A2: Explicit cash flows and returns for equity and debt investors under each structure.
A3: All figures are hypothetical and illustrative.
A5: Equity investor cash flows (USD millions)
A6: Structure | B6: Close | C6: Year 1 | D6: Year 2 | E6: Year 3 | F6: Year 4 | G6: Year 5
A7: Growth equity | B7: =-'Growth Equity Case'!B25 | C7: 0 | D7: 0 | E7: 0 | F7: 0 | G7: ='Growth Equity Case'!B26
A8: Blended capital | B8: =-'Blended Capital Case'!B37 | C8: 0 | D8: 0 | E8: 0 | F8: 0 | G8: ='Blended Capital Case'!B38
A10: Equity investor returns
A11: Metric | B11: Growth equity | C11: Private credit | D11: Blended capital
A12: Equity invested | B12: ='Growth Equity Case'!B25 | C12: =0 | D12: ='Blended Capital Case'!B37
A13: Investor ownership | B13: ='Growth Equity Case'!B24 | C13: =0 | D13: ='Blended Capital Case'!B36
A14: Exit equity value | B14: ='Growth Equity Case'!B23 | C14: ='Private Credit Case'!B35 | D14: ='Blended Capital Case'!B35
A15: Equity investor proceeds | B15: ='Growth Equity Case'!B26 | C15: =0 | D15: ='Blended Capital Case'!B38
A16: MOIC | B16: ='Growth Equity Case'!B27 | C16: ="n/a" | D16: ='Blended Capital Case'!B39
A17: IRR (5 year hold) | B17: =IRR(B7:G7) | C17: ="n/a" | D17: =IRR(B8:G8)
A18: Founder and existing holder dilution | B18: ='Capital Structures'!B19 | C18: ='Capital Structures'!C19 | D18: ='Capital Structures'!D19
A20: Debt investor returns
A21: Metric | B21: Growth equity | C21: Private credit | D21: Blended capital
A22: Net outlay at close | B22: ="n/a" | C22: ='Private Credit Case'!B45 | D22: ='Blended Capital Case'!B45
A23: Total received over five years | B23: ="n/a" | C23: ='Private Credit Case'!B49 | D23: ='Blended Capital Case'!B49
A24: Debt investor MOIC | B24: ="n/a" | C24: ='Private Credit Case'!B50 | D24: ='Blended Capital Case'!B50
A26: Debt investor cash flows (USD millions)
A27: Structure | B27: Close | C27: Year 1 | D27: Year 2 | E27: Year 3 | F27: Year 4 | G27: Year 5
A28: Private credit | B28: =-'Private Credit Case'!B45 | C28: ='Private Credit Case'!B8+'Private Credit Case'!B10 | D28: ='Private Credit Case'!C8+'Private Credit Case'!C10 | E28: ='Private Credit Case'!D8+'Private Credit Case'!D10 | F28: ='Private Credit Case'!E8+'Private Credit Case'!E10 | G28: ='Private Credit Case'!F8+'Private Credit Case'!F10+'Private Credit Case'!F12
A29: Blended capital | B29: =-'Blended Capital Case'!B45 | C29: ='Blended Capital Case'!B8+'Blended Capital Case'!B10 | D29: ='Blended Capital Case'!C8+'Blended Capital Case'!C10 | E29: ='Blended Capital Case'!D8+'Blended Capital Case'!D10 | F29: ='Blended Capital Case'!E8+'Blended Capital Case'!E10 | G29: ='Blended Capital Case'!F8+'Blended Capital Case'!F10+'Blended Capital Case'!F12
A30: Debt investor IRR | B30: ="n/a" | C30: =IRR(B28:G28) | D30: =IRR(B29:G29)
A32: The equity investor MOIC is higher under the blended structure than under all equity, because a smaller cheque is exposed to the same enterprise value appreciation. That is the return argument for the blend. The dilution argument is stronger still, and the covenant argument is what makes the all debt structure unavailable.
A34: All figures are hypothetical and illustrative.

Sheet Sensitivities
A1: Sensitivities
A2: Each table moves one driver and holds everything else constant, so the effect is attributable.
A3: All figures are hypothetical and illustrative.
A5: Exit multiple sensitivity, blended capital equity investor
A6: Year five ARR and ending cash are held at the base case. Only the exit ARR multiple moves.
A7: Exit ARR multiple | B7: Enterprise value | C7: Exit equity value | D7: Proceeds | E7: MOIC | F7: IRR
A8: 5 | B8: ='Blended Capital Case'!B30*A8 | C8: =B8+'Blended Capital Case'!B33+'Blended Capital Case'!B34 | D8: =C8*'Blended Capital Case'!B36 | E8: =D8/'Blended Capital Case'!B37 | F8: =E8^(1/5)-1
A9: 6 | B9: ='Blended Capital Case'!B30*A9 | C9: =B9+'Blended Capital Case'!B33+'Blended Capital Case'!B34 | D9: =C9*'Blended Capital Case'!B36 | E9: =D9/'Blended Capital Case'!B37 | F9: =E9^(1/5)-1
A10: 7 | B10: ='Blended Capital Case'!B30*A10 | C10: =B10+'Blended Capital Case'!B33+'Blended Capital Case'!B34 | D10: =C10*'Blended Capital Case'!B36 | E10: =D10/'Blended Capital Case'!B37 | F10: =E10^(1/5)-1
A11: 8 | B11: ='Blended Capital Case'!B30*A11 | C11: =B11+'Blended Capital Case'!B33+'Blended Capital Case'!B34 | D11: =C11*'Blended Capital Case'!B36 | E11: =D11/'Blended Capital Case'!B37 | F11: =E11^(1/5)-1
A12: 9 | B12: ='Blended Capital Case'!B30*A12 | C12: =B12+'Blended Capital Case'!B33+'Blended Capital Case'!B34 | D12: =C12*'Blended Capital Case'!B36 | E12: =D12/'Blended Capital Case'!B37 | F12: =E12^(1/5)-1
A14: ARR growth sensitivity
A15: Year one growth varies. The same annual decay applies in later years.
A16: Year 1 ARR growth | B16: Year 5 ending ARR | C16: Exit enterprise value at base multiple
A17: 0.2 | B17: =Assumptions!$B$6*(1+MAX(0,A17-Assumptions!$B$8*0))*(1+MAX(0,A17-Assumptions!$B$8*1))*(1+MAX(0,A17-Assumptions!$B$8*2))*(1+MAX(0,A17-Assumptions!$B$8*3))*(1+MAX(0,A17-Assumptions!$B$8*4)) | C17: =B17*Assumptions!$B$29
A18: 0.25 | B18: =Assumptions!$B$6*(1+MAX(0,A18-Assumptions!$B$8*0))*(1+MAX(0,A18-Assumptions!$B$8*1))*(1+MAX(0,A18-Assumptions!$B$8*2))*(1+MAX(0,A18-Assumptions!$B$8*3))*(1+MAX(0,A18-Assumptions!$B$8*4)) | C18: =B18*Assumptions!$B$29
A19: 0.3 | B19: =Assumptions!$B$6*(1+MAX(0,A19-Assumptions!$B$8*0))*(1+MAX(0,A19-Assumptions!$B$8*1))*(1+MAX(0,A19-Assumptions!$B$8*2))*(1+MAX(0,A19-Assumptions!$B$8*3))*(1+MAX(0,A19-Assumptions!$B$8*4)) | C19: =B19*Assumptions!$B$29
A20: 0.35 | B20: =Assumptions!$B$6*(1+MAX(0,A20-Assumptions!$B$8*0))*(1+MAX(0,A20-Assumptions!$B$8*1))*(1+MAX(0,A20-Assumptions!$B$8*2))*(1+MAX(0,A20-Assumptions!$B$8*3))*(1+MAX(0,A20-Assumptions!$B$8*4)) | C20: =B20*Assumptions!$B$29
A21: 0.4 | B21: =Assumptions!$B$6*(1+MAX(0,A21-Assumptions!$B$8*0))*(1+MAX(0,A21-Assumptions!$B$8*1))*(1+MAX(0,A21-Assumptions!$B$8*2))*(1+MAX(0,A21-Assumptions!$B$8*3))*(1+MAX(0,A21-Assumptions!$B$8*4)) | C21: =B21*Assumptions!$B$29
A23: Retention sensitivity
A24: Net revenue retention varies while the ARR growth target is held fixed, so lower retention simply raises the New ARR the sales team must win.
A25: Net revenue retention | B25: Year 1 New ARR required | C25: Increase over base case | D25: Implied year 1 CAC payback (months)
A26: 1 | B26: =Assumptions!$B$6*(1+'Operating Forecast'!B8)-Assumptions!$B$6*A26 | C26: =B26-'Operating Forecast'!B9 | D26: =-'Operating Forecast'!B18/((B26+Assumptions!$B$6*(A26-Assumptions!$B$10))*Assumptions!$B$11)*12
A27: 1.05 | B27: =Assumptions!$B$6*(1+'Operating Forecast'!B8)-Assumptions!$B$6*A27 | C27: =B27-'Operating Forecast'!B9 | D27: =-'Operating Forecast'!B18/((B27+Assumptions!$B$6*(A27-Assumptions!$B$10))*Assumptions!$B$11)*12
A28: 1.1 | B28: =Assumptions!$B$6*(1+'Operating Forecast'!B8)-Assumptions!$B$6*A28 | C28: =B28-'Operating Forecast'!B9 | D28: =-'Operating Forecast'!B18/((B28+Assumptions!$B$6*(A28-Assumptions!$B$10))*Assumptions!$B$11)*12
A29: 1.15 | B29: =Assumptions!$B$6*(1+'Operating Forecast'!B8)-Assumptions!$B$6*A29 | C29: =B29-'Operating Forecast'!B9 | D29: =-'Operating Forecast'!B18/((B29+Assumptions!$B$6*(A29-Assumptions!$B$10))*Assumptions!$B$11)*12
A30: 1.2 | B30: =Assumptions!$B$6*(1+'Operating Forecast'!B8)-Assumptions!$B$6*A30 | C30: =B30-'Operating Forecast'!B9 | D30: =-'Operating Forecast'!B18/((B30+Assumptions!$B$6*(A30-Assumptions!$B$10))*Assumptions!$B$11)*12
A32: Interest rate sensitivity, blended capital facility
A33: Applied to the blended facility principal. Shows where the minimum cash covenant starts to bind.
A34: Cash interest rate | B34: Year 1 cash interest | C34: Five year cash interest | D34: Year 5 closing cash | E34: Covenant status
A35: 0.09 | B35: =Assumptions!$B$46*A35 | C35: =Assumptions!$B$46*A35*Assumptions!$B$51+(Assumptions!$B$46*A35+(Assumptions!$B$46-Assumptions!$B$46*Assumptions!$B$52)*A35) | D35: ='Blended Capital Case'!F23+(SUM('Blended Capital Case'!B8:F8)-C35) | E35: =IF(D35<Assumptions!$B$30,"BREACH","Headroom")
A36: 0.1 | B36: =Assumptions!$B$46*A36 | C36: =Assumptions!$B$46*A36*Assumptions!$B$51+(Assumptions!$B$46*A36+(Assumptions!$B$46-Assumptions!$B$46*Assumptions!$B$52)*A36) | D36: ='Blended Capital Case'!F23+(SUM('Blended Capital Case'!B8:F8)-C36) | E36: =IF(D36<Assumptions!$B$30,"BREACH","Headroom")
A37: 0.11 | B37: =Assumptions!$B$46*A37 | C37: =Assumptions!$B$46*A37*Assumptions!$B$51+(Assumptions!$B$46*A37+(Assumptions!$B$46-Assumptions!$B$46*Assumptions!$B$52)*A37) | D37: ='Blended Capital Case'!F23+(SUM('Blended Capital Case'!B8:F8)-C37) | E37: =IF(D37<Assumptions!$B$30,"BREACH","Headroom")
A38: 0.12 | B38: =Assumptions!$B$46*A38 | C38: =Assumptions!$B$46*A38*Assumptions!$B$51+(Assumptions!$B$46*A38+(Assumptions!$B$46-Assumptions!$B$46*Assumptions!$B$52)*A38) | D38: ='Blended Capital Case'!F23+(SUM('Blended Capital Case'!B8:F8)-C38) | E38: =IF(D38<Assumptions!$B$30,"BREACH","Headroom")
A39: 0.13 | B39: =Assumptions!$B$46*A39 | C39: =Assumptions!$B$46*A39*Assumptions!$B$51+(Assumptions!$B$46*A39+(Assumptions!$B$46-Assumptions!$B$46*Assumptions!$B$52)*A39) | D39: ='Blended Capital Case'!F23+(SUM('Blended Capital Case'!B8:F8)-C39) | E39: =IF(D39<Assumptions!$B$30,"BREACH","Headroom")
A41: Break even analysis
A42: At what point the cost structure stops consuming cash.
A43: Year 5 operating expenses as a percentage of revenue | B43: =-'Operating Forecast'!F21/'Operating Forecast'!F15
A44: Gross margin | B44: =Assumptions!$B$11
A45: Contribution margin at the year 5 cost structure | B45: =Assumptions!$B$11+'Operating Forecast'!F21/'Operating Forecast'!F15
...

Sheet Downside Case
A1: Downside Case
A2: Lower growth, no net expansion, higher churn, thinner margin, and sales spend that does not fall. This is the test that separates the three structures.
A3: All figures are hypothetical and illustrative.
A5: Line item (USD millions) | B5: Year 1 | C5: Year 2 | D5: Year 3 | E5: Year 4 | F5: Year 5
A6: Beginning ARR | B6: =Assumptions!$B$6 | C6: =B8 | D6: =C8 | E6: =D8 | F6: =E8
A7: Growth rate | B7: =MAX(0,Assumptions!$B$55-Assumptions!$B$8*0) | C7: =MAX(0,Assumptions!$B$55-Assumptions!$B$8*1) | D7: =MAX(0,Assumptions!$B$55-Assumptions!$B$8*2) | E7: =MAX(0,Assumptions!$B$55-Assumptions!$B$8*3) | F7: =MAX(0,Assumptions!$B$55-Assumptions!$B$8*4)
A8: Ending ARR | B8: =B6*(1+B7) | C8: =C6*(1+C7) | D8: =D6*(1+D7) | E8: =E6*(1+E7) | F8: =F6*(1+F7)
A9: New ARR required | B9: =B8-B6*Assumptions!$B$56 | C9: =C8-C6*Assumptions!$B$56 | D9: =D8-D6*Assumptions!$B$56 | E9: =E8-E6*Assumptions!$B$56 | F9: =F8-F6*Assumptions!$B$56
A10: Churned ARR | B10: =-B6*(1-Assumptions!$B$57) | C10: =-C6*(1-Assumptions!$B$57) | D10: =-D6*(1-Assumptions!$B$57) | E10: =-E6*(1-Assumptions!$B$57) | F10: =-F6*(1-Assumptions!$B$57)
A11: Revenue | B11: =(B6+B8)/2 | C11: =(C6+C8)/2 | D11: =(D6+D8)/2 | E11: =(E6+E8)/2 | F11: =(F6+F8)/2
A12: Gross profit | B12: =B11*Assumptions!$B$58 | C12: =C11*Assumptions!$B$58 | D12: =D11*Assumptions!$B$58 | E12: =E11*Assumptions!$B$58 | F12: =F11*Assumptions!$B$58
A13: Total operating expenses | B13: =-B11*(Assumptions!B$21+Assumptions!$B$59+Assumptions!B$22+Assumptions!B$23) | C13: =-C11*(Assumptions!C$21+Assumptions!$B$59+Assumptions!C$22+Assumptions!C$23) | D13: =-D11*(Assumptions!D$21+Assumptions!$B$59+Assumptions!D$22+Assumptions!D$23) | E13: =-E11*(Assumptions!E$21+Assumptions!$B$59+Assumptions!E$22+Assumptions!E$23) | F13: =-F11*(Assumptions!F$21+Assumptions!$B$59+Assumptions!F$22+Assumptions!F$23)
A14: EBITDA | B14: =B12+B13 | C14: =C12+C13 | D14: =D12+D13 | E14: =E12+E13 | F14: =F12+F13
A15: Capital expenditure | B15: =-B11*Assumptions!$B$12 | C15: =-C11*Assumptions!$B$12 | D15: =-D11*Assumptions!$B$12 | E15: =-E11*Assumptions!$B$12 | F15: =-F11*Assumptions!$B$12
A16: Deferred revenue benefit | B16: =(B8-B6)*Assumptions!$B$13 | C16: =(C8-C6)*Assumptions!$B$13 | D16: =(D8-D6)*Assumptions!$B$13 | E16: =(E8-E6)*Assumptions!$B$13 | F16: =(F8-F6)*Assumptions!$B$13
A17: Unlevered free cash flow | B17: =B14+B15+B16 | C17: =C14+C15+C16 | D17: =D14+D15+D16 | E17: =E14+E15+E16 | F17: =F14+F15+F16
A19: Cash outcome under each structure
A20: Closing cash (USD millions) | B20: Year 1 | C20: Year 2 | D20: Year 3 | E20: Year 4 | F20: Year 5
A21: Growth equity | B21: ='Capital Structures'!B13+B17 | C21: =B21+C17 | D21: =C21+D17 | E21: =D21+E17 | F21: =E21+F17
A22: Private credit | B22: ='Capital Structures'!C13+B17-'Private Credit Case'!B8-'Private Credit Case'!B10 | C22: =B22+C17-'Private Credit Case'!C8-'Private Credit Case'!C10 | D22: =C22+D17-'Private Credit Case'!D8-'Private Credit Case'!D10 | E22: =D22+E17-'Private Credit Case'!E8-'Private Credit Case'!E10 | F22: =E22+F17-'Private Credit Case'!F8-'Private Credit Case'!F10
A23: Blended capital | B23: ='Capital Structures'!D13+B17-'Blended Capital Case'!B8-'Blended Capital Case'!B10 | C23: =B23+C17-'Blended Capital Case'!C8-'Blended Capital Case'!C10 | D23: =C23+D17-'Blended Capital Case'!D8-'Blended Capital Case'!D10 | E23: =D23+E17-'Blended Capital Case'!E8-'Blended Capital Case'!E10 | F23: =E23+F17-'Blended Capital Case'!F8-'Blended Capital Case'!F10
A25: Structure | B25: Year 5 cash | C25: Survives five years | D25: Assessment
A26: Growth equity | B26: =F21 | C26: =IF(F21>0,"Yes","No") | D26: =IF(F21<=0,"Fails: runs out of cash",IF(MIN(B21:F21)<Assumptions!$B$30,"Survives but breaches the minimum cash covenant","Survives with covenant headroom"))
A27: Private credit | B27: =F22 | C27: =IF(F22>0,"Yes","No") | D27: =IF(F22<=0,"Fails: runs out of cash",IF(MIN(B22:F22)<Assumptions!$B$30,"Survives but breaches the minimum cash covenant","Survives with covenant headroom"))
A28: Blended capital | B28: =F23 | C28: =IF(F23>0,"Yes","No") | D28: =IF(F23<=0,"Fails: runs out of cash",IF(MIN(B23:F23)<Assumptions!$B$30,"Survives but breaches the minimum cash covenant","Survives with covenant headroom"))
A30: This is the honest boundary of the recommendation. In the base case the blended structure is clearly best. In the downside case it survives only narrowly and breaches the minimum cash covenant, while the all debt structure fails outright and the all equity structure is comfortable. A reader who assigns a high probability to the downside should prefer more equity in the mix, and the equity component is an input on the Assumptions sheet precisely so that view can be tested.
A32: All figures are hypothetical and illustrative.

Sheet Sources and Disclosures
A1: Sources and Disclosures
A2: What this workbook is, what it is not, and where its inputs come from.
A4: Hypothetical company | B4: Northstar Workflow Systems is a hypothetical company created solely for an illustrative underwriting exercise. It is not a real business or investment opportunity.
A5: Illustrative figures | B5: All operating, financial, and transaction assumptions in this workbook are illustrative. They do not represent an actual company, an actual financing, or an investment recommendation. Every output sheet carries the line: All figures are hypothetical and illustrative.
A6: Project disclosure | B6: This is an independent work sample built by Sahil Modi. It is not affiliated with or endorsed by any investment firm. The private company universe published alongside this model is based on dated public sources, and missing information there is identified as not publicly disclosed.
A7: Source of the assumptions | B7: The assumptions were chosen to represent a plausible mid stage B2B enterprise SaaS company at the point where a growth financing decision becomes unavoidable: roughly USD 12 million of ARR, growth in the low thirties, net revenue retention above 100 percent, gross retention in the high eighties, gross margin near 80 percent, and negative EBITDA. They are not drawn from any real company.
A8: Relationship to the company universe | B8: No company in the real private company universe appears in this workbook, and this hypothetical company appears nowhere in that universe. The separation is enforced by automated tests in the repository.
A9: Debt terms | B9: Pricing, tenor, amortisation, original issue discount, and covenant levels are illustrative and set at levels broadly consistent with senior secured growth facilities for software companies. They are not quotes and do not reflect any lender's actual terms.
A10: What has been deliberately excluded | B10: No estimate of any real company's ARR, revenue, retention, gross margin, EBITDA, burn, runway, valuation, customer concentration, debt balance, covenants, profitability, founder ownership, or exit value appears anywhere in this workbook or in the accompanying research.
A11: Development disclosure | B11: Sahil Modi designed the research framework, scoring logic, underwriting structure, and investment analysis. AI-assisted development tools were used to support coding, research organization, testing, and document production. Every company record and material claim was reviewed against dated public sources.
A12: Repository | B12: Source code, the company research records, and the script that generates this workbook are public at https://github.com/smodi13/growth-capital-origination-engine
A13: Contact | B13: Sahil Modi, modi.sahil@gmail.com
